Workbook
Name Setores: CONFIG!$A$12:$A$40

Sheet INÍCIO
A1: GSL BARTOFIL · CALENDÁRIO DE GESTÃO OPERACIONAL 2026
A3: Turnos A (manhã) · B (tarde) · C (noite) · Reunião semanal com a gerência às sextas-feiras
A5: MODELOS PARA DOWNLOAD — clique no link, baixe, preencha e anexe pelo menu GSL Bartofil > Anexar entrega
A6: 1. | B6: Erros Operacionais (SEG) — Modelo-Erros-Operacionais.docx | C6: (administrador: cole aqui o link do arquivo no Drive)
A7: 2. | B7: Suporte de Supervisores (TER) — Modelo-Suporte-Supervisores.docx | C7: (administrador: cole aqui o link do arquivo no Drive)
A8: 3. | B8: Metas (QUI) — Modelo-Metas.docx | C8: (administrador: cole aqui o link do arquivo no Drive)
A9: 4. | B9: Faltas e Atestados (SEX) — Modelo-Faltas-Atestados.docx | C9: (administrador: cole aqui o link do arquivo no Drive)
A10: 5. | B10: Acompanhamento c/ Supervisores (SEX) — Modelo-Acompanhamento-Supervisores.docx | C10: (administrador: cole aqui o link do arquivo no Drive)
A11: 6. | B11: Checklist de Vistoria (QUA) — Checklist-Vistoria.docx | C11: (administrador: cole aqui o link do arquivo no Drive)
A12: Os links devem estar compartilhados como 'qualquer pessoa com o link pode ver'. Os mesmos links vão automaticamente nos e-mails de lembrete e cobrança de cada atividade.
A14: COMO FUNCIONA
A15: 1. | B15: Cada mês é uma aba-calendário. As atividades são distribuídas na semana — SEG Erros, TER Suporte, QUA Vistoria, QUI Metas, SEX Faltas + Acompanhamento c/ Supervisores + Reunião Semanal com a Gerência (agora rastreada: aparece no mostrador, dispara lembrete e o gerente pode mudar a data ou cancelar). O MOSTRADOR exibe o nome de cada atividade sob o seu dia; dias com prazo ficam azuis e o dia de hoje amarelo. Se o gerente mudar um prazo ou cancelar, o mostrador se atualiza sozinho.
A16: 2. | B16: Abaixo do calendário fica a GESTÃO DE ATIVIDADES: uma linha por atividade x turno x semana. Para entregar, o coordenador baixa o modelo Word da atividade (pasta Modelos do Drive), preenche, e usa o menu GSL Bartofil > Anexar entrega: escolhe o arquivo e o script sobe direto para a pasta do Drive da GSL, cola o link e avisa o gerente. (Também é possível colar o link manualmente na coluna LINK DO ANEXO.)
A17: 3. | B17: O gerente valida na coluna J (Aprovado/Reprovado). Se reprovar, preenche o MOTIVO na coluna K — o coordenador recebe tudo por e-mail.
A18: 4. | B18: O gerente pode ALTERAR QUALQUER PRAZO na coluna C (células amarelas). A mudança dispara e-mail automático avisando os coordenadores, e o calendário de parede se recolore sozinho.
A19: 5. | B19: Na vistoria (Acomp. Organizacional Setorial), o gerente define o SETOR na planilha; o coordenador do turno é avisado por e-mail, imprime o Checklist de Vistoria (arquivo Word), preenche no setor, escaneia e anexa.
A20: 6. | B20: Treinamentos: o gerente preenche prazo + tema na seção TREINAMENTOS no fim de cada aba mensal; os coordenadores recebem o aviso por e-mail com a data.
A21: 7. | B21: GERENTE e ADMINISTRADOR (CONFIG!B9) podem CANCELAR uma atividade: selecione a linha e use GSL Bartofil > Cancelar atividade (ou escolha Cancelada na coluna VALIDAÇÃO). A atividade sai do mostrador e das contagens, e os coordenadores são avisados por e-mail com o motivo.
A22: 8. | B22: A aba CENTRAL mostra o andamento mês a mês (% concluído, pendentes, atrasadas) e a CONFIG cadastra nomes, e-mails, setores e parâmetros.
A24: ATIVIDADES E FREQUÊNCIA
B25: Levantamento de Erros Operacionais | C25: Semanal (SEG) — principais erros da semana + ações corretivas tomadas. Modelo Word: Modelo-Erros-Operacionais.docx.
B26: Suporte de Supervisores | C26: Semanal (TER) — situação do setor, fluidez, atrasos e trocas de turno. Modelo Word: Modelo-Suporte-Supervisores.docx.
B27: Acomp. Organizacional Setorial | C27: Semanal (QUA) — vistoria no setor definido pelo gerente, com o Checklist-Vistoria.docx impresso, preenchido, escaneado e anexado.
B28: Metas | C28: Semanal (QUI) — indicadores, atingimento e feedback dos supervisores sobre colaboradores (destaques e atípicos). Modelo Word: Modelo-Metas.docx.
B29: Faltas e Atestados | C29: Semanal (SEX) — absenteísmo: faltas e atestados da semana. Modelo Word: Modelo-Faltas-Atestados.docx.
B30: Acompanhamento Semanal c/ Supervisores | C30: Semanal (SEX) — retorno colhido com os supervisores sobre desempenho das equipes. Modelo Word: Modelo-Acompanhamento-Supervisores.docx.
B31: Reunião Semanal com a Gerência | C31: Semanal (SEX) — reunião dos 3 coordenadores com o gerente; após realizada, o gerente marca Aprovado (ata opcional no LINK DO ANEXO). O gerente pode mudar a data da semana editando o PRAZO da linha.
B32: Programação de Férias | C32: Mensal (1ª segunda) — alinhamento com os supervisores sobre os feristas do mês.
B33: Mudança de Função | C33: Mensal (última sexta) — reunião sobre movimentação de pessoal; o gerente pode mudar a data.
B34: Treinamento com Colaboradores | C34: Programado — só aparece quando o gerente marca; coordenadores programam dia/hora com os supervisores.
A36: APÓS IMPORTAR NO GOOGLE SHEETS — ATIVAR OS E-MAILS AUTOMÁTICOS (5 min)
A37: 1. | B37: OBRIGATÓRIO: abra o arquivo no Google e use Arquivo → Salvar como Planilhas Google. Em modo .xlsx (aparece 'XLSX' ao lado do nome) o Apps Script NÃO funciona — menu, anexos e e-mails ficam mortos.
A38: 2. | B38: Extensões → Apps Script. Apague o conteúdo, cole o arquivo Code.gs entregue junto com esta planilha e salve.
A39: 3. | B39: Preencha a aba CONFIG (nomes e e-mails dos 3 coordenadores e do gerente).
A40: 4. | B40: No Apps Script, execute a função instalarGatilhos uma vez e autorize com a conta do gerente (os e-mails sairão dela).
A41: 5. | B41: Pronto. Lembretes (2 dias antes e no dia do prazo), COBRANÇA AUTOMÁTICA DE ATRASO (reenviada a cada 3 dias ao coordenador, com cópia à gestão, até a entrega), confirmação de entrega, aprovação/reprovação com motivo, mudança de prazo, setor da vistoria e treinamentos — tudo automático.
A42: 6. | B42: Recarregue a página: o menu GSL Bartofil aparece na barra. Cada coordenador, no 1º uso do Anexar entrega, autoriza o script uma única vez.
A43: 7. | B43: Suba os 6 arquivos Word de modelo na subpasta Modelos da pasta GSL Bartofil - Entregas do Drive e cole o link de cada um na tabela MODELOS PARA DOWNLOAD, no topo desta aba: os e-mails de lembrete passam a levar o link do modelo.
A44: 8. | B44: Recomendado: proteja as colunas do gerente (PRAZO C, SETOR J, VALIDAÇÃO O, MOTIVO P) em Dados → Proteger intervalos, liberando gerente e administrador.
A46: IDENTIDADE VISUAL
...

Sheet CENTRAL
A1: CENTRAL — ANDAMENTO 2026 | I1: GSL BARTOFIL
A3: TOTAL NO ANO | C3: APROVADAS | E3: ATRASADAS AGORA | G3: % CONCLUÍDO DO ANO | I3: =TEXT(TODAY(),"dd/mm/yyyy")&" — visão geral"
A4: =SUM(B8:B13) | C4: =SUM(C8:C13) | E4: =SUM(F8:F13) | G4: =IF(SUM(B8:B13)=0,0,SUM(C8:C13)/SUM(B8:B13))
A6: ANDAMENTO MÊS A MÊS
A7: MÊS | B7: TOTAL | C7: APROV. | D7: AGUARD. VALID. | E7: PEND. | F7: ATRAS. | G7: REPROV. | H7: % CONCL. | I7: PROGRESSO | J7: SITUAÇÃO
A8: JUL 2026 | B8: =COUNTIF('JUL 2026'!$R$22:$R$210,"Aprovada")+COUNTIF('JUL 2026'!$R$22:$R$210,"Entregue")+COUNTIF('JUL 2026'!$R$22:$R$210,"Pendente")+COUNTIF('JUL 2026'!$R$22:$R$210,"Atrasada")+COUNTIF('JUL 2026'!$R$22:$R$210,"Reprovada") | C8: =COUNTIF('JUL 2026'!$R$22:$R$210,"Aprovada") | D8: =COUNTIF('JUL 2026'!$R$22:$R$210,"Entregue") | E8: =COUNTIF('JUL 2026'!$R$22:$R$210,"Pendente") | F8: =COUNTIF('JUL 2026'!$R$22:$R$210,"Atrasada") | G8: =COUNTIF('JUL 2026'!$R$22:$R$210,"Reprovada") | H8: =IF($B8=0,0,$C8/$B8) | I8: =REPT("█",ROUND($H8*15,0))&REPT("░",15-ROUND($H8*15,0)) | J8: =IF($B8=0,"—",IF($C8=$B8,"Concluído",IF($F8>0,"Com atrasos","Em andamento")))
A9: AGO 2026 | B9: =COUNTIF('AGO 2026'!$R$22:$R$210,"Aprovada")+COUNTIF('AGO 2026'!$R$22:$R$210,"Entregue")+COUNTIF('AGO 2026'!$R$22:$R$210,"Pendente")+COUNTIF('AGO 2026'!$R$22:$R$210,"Atrasada")+COUNTIF('AGO 2026'!$R$22:$R$210,"Reprovada") | C9: =COUNTIF('AGO 2026'!$R$22:$R$210,"Aprovada") | D9: =COUNTIF('AGO 2026'!$R$22:$R$210,"Entregue") | E9: =COUNTIF('AGO 2026'!$R$22:$R$210,"Pendente") | F9: =COUNTIF('AGO 2026'!$R$22:$R$210,"Atrasada") | G9: =COUNTIF('AGO 2026'!$R$22:$R$210,"Reprovada") | H9: =IF($B9=0,0,$C9/$B9) | I9: =REPT("█",ROUND($H9*15,0))&REPT("░",15-ROUND($H9*15,0)) | J9: =IF($B9=0,"—",IF($C9=$B9,"Concluído",IF($F9>0,"Com atrasos","Em andamento")))
A10: SET 2026 | B10: =COUNTIF('SET 2026'!$R$22:$R$210,"Aprovada")+COUNTIF('SET 2026'!$R$22:$R$210,"Entregue")+COUNTIF('SET 2026'!$R$22:$R$210,"Pendente")+COUNTIF('SET 2026'!$R$22:$R$210,"Atrasada")+COUNTIF('SET 2026'!$R$22:$R$210,"Reprovada") | C10: =COUNTIF('SET 2026'!$R$22:$R$210,"Aprovada") | D10: =COUNTIF('SET 2026'!$R$22:$R$210,"Entregue") | E10: =COUNTIF('SET 2026'!$R$22:$R$210,"Pendente") | F10: =COUNTIF('SET 2026'!$R$22:$R$210,"Atrasada") | G10: =COUNTIF('SET 2026'!$R$22:$R$210,"Reprovada") | H10: =IF($B10=0,0,$C10/$B10) | I10: =REPT("█",ROUND($H10*15,0))&REPT("░",15-ROUND($H10*15,0)) | J10: =IF($B10=0,"—",IF($C10=$B10,"Concluído",IF($F10>0,"Com atrasos","Em andamento")))
A11: OUT 2026 | B11: =COUNTIF('OUT 2026'!$R$22:$R$210,"Aprovada")+COUNTIF('OUT 2026'!$R$22:$R$210,"Entregue")+COUNTIF('OUT 2026'!$R$22:$R$210,"Pendente")+COUNTIF('OUT 2026'!$R$22:$R$210,"Atrasada")+COUNTIF('OUT 2026'!$R$22:$R$210,"Reprovada") | C11: =COUNTIF('OUT 2026'!$R$22:$R$210,"Aprovada") | D11: =COUNTIF('OUT 2026'!$R$22:$R$210,"Entregue") | E11: =COUNTIF('OUT 2026'!$R$22:$R$210,"Pendente") | F11: =COUNTIF('OUT 2026'!$R$22:$R$210,"Atrasada") | G11: =COUNTIF('OUT 2026'!$R$22:$R$210,"Reprovada") | H11: =IF($B11=0,0,$C11/$B11) | I11: =REPT("█",ROUND($H11*15,0))&REPT("░",15-ROUND($H11*15,0)) | J11: =IF($B11=0,"—",IF($C11=$B11,"Concluído",IF($F11>0,"Com atrasos","Em andamento")))
A12: NOV 2026 | B12: =COUNTIF('NOV 2026'!$R$22:$R$210,"Aprovada")+COUNTIF('NOV 2026'!$R$22:$R$210,"Entregue")+COUNTIF('NOV 2026'!$R$22:$R$210,"Pendente")+COUNTIF('NOV 2026'!$R$22:$R$210,"Atrasada")+COUNTIF('NOV 2026'!$R$22:$R$210,"Reprovada") | C12: =COUNTIF('NOV 2026'!$R$22:$R$210,"Aprovada") | D12: =COUNTIF('NOV 2026'!$R$22:$R$210,"Entregue") | E12: =COUNTIF('NOV 2026'!$R$22:$R$210,"Pendente") | F12: =COUNTIF('NOV 2026'!$R$22:$R$210,"Atrasada") | G12: =COUNTIF('NOV 2026'!$R$22:$R$210,"Reprovada") | H12: =IF($B12=0,0,$C12/$B12) | I12: =REPT("█",ROUND($H12*15,0))&REPT("░",15-ROUND($H12*15,0)) | J12: =IF($B12=0,"—",IF($C12=$B12,"Concluído",IF($F12>0,"Com atrasos","Em andamento")))
A13: DEZ 2026 | B13: =COUNTIF('DEZ 2026'!$R$22:$R$210,"Aprovada")+COUNTIF('DEZ 2026'!$R$22:$R$210,"Entregue")+COUNTIF('DEZ 2026'!$R$22:$R$210,"Pendente")+COUNTIF('DEZ 2026'!$R$22:$R$210,"Atrasada")+COUNTIF('DEZ 2026'!$R$22:$R$210,"Reprovada") | C13: =COUNTIF('DEZ 2026'!$R$22:$R$210,"Aprovada") | D13: =COUNTIF('DEZ 2026'!$R$22:$R$210,"Entregue") | E13: =COUNTIF('DEZ 2026'!$R$22:$R$210,"Pendente") | F13: =COUNTIF('DEZ 2026'!$R$22:$R$210,"Atrasada") | G13: =COUNTIF('DEZ 2026'!$R$22:$R$210,"Reprovada") | H13: =IF($B13=0,0,$C13/$B13) | I13: =REPT("█",ROUND($H13*15,0))&REPT("░",15-ROUND($H13*15,0)) | J13: =IF($B13=0,"—",IF($C13=$B13,"Concluído",IF($F13>0,"Com atrasos","Em andamento")))
A14: TOTAL 2026 | B14: =SUM(B8:B13) | C14: =SUM(C8:C13) | D14: =SUM(D8:D13) | E14: =SUM(E8:E13) | F14: =SUM(F8:F13) | G14: =SUM(G8:G13) | H14: =IF($B14=0,0,$C14/$B14) | I14: =REPT("█",ROUND($H14*15,0))&REPT("░",15-ROUND($H14*15,0)) | J14: =""
A16: Os números somam as entregas dos 3 turnos (A, B e C) + treinamentos programados. Aguard. valid. = anexado pelo coordenador e aguardando aprovação do gerente.

Sheet CONFIG
A1: CONFIG — ENVOLVIDOS, SETORES, PARÂMETROS E MODELOS
A3: 1 · EQUIPE (usada nas fórmulas e nos e-mails do script)
A4: PAPEL | B4: NOME | C4: E-MAIL
A5: Coordenador · Turno A (manhã) | B5: (preencha o nome) | C5: turnoA@bartofil.com.br
A6: Coordenador · Turno B (tarde) | B6: (preencha o nome) | C6: turnoB@bartofil.com.br
A7: Coordenador · Turno C (noite) | B7: (preencha o nome) | C7: turnoC@bartofil.com.br
A8: Gerente de Logística | B8: (preencha o nome) | C8: gerente@bartofil.com.br
A9: Administrador da planilha | B9: Hércules | C9: hercules@bartofil.com.br
A11: 2 · SETORES DO CD (lista usada no campo 'Setor' da vistoria) | C11: 3 · PARÂMETROS DO SCRIPT
A12: Recebimento | C12: Dias de antecedência do lembrete | D12: 2
A13: Conferência | C13: Reenviar alerta de atraso a cada (dias) | D13: 3
A14: Armazenagem / Porta-paletes | C14: E-mail em cópia (opcional)
A15: Separação (Picking) | C15: Pasta do Drive p/ entregas (o script cria e preenche)
A16: Reposição
A17: Expedição
A18: Carregamento / Docas
A19: Devolução / Avarias
A20: Inventário
A21: Manutenção
A22: Pátio / Área externa
A23: Administrativo do CD
A26: Células em amarelo são editáveis. NÃO mova linhas/colunas desta aba: o script lê B5:C9 (equipe), D12:D14 (parâmetros) e D15 (pasta do Drive). Os links dos modelos ficam na aba INÍCIO (C6:C11). Gerente e Administrador podem validar e CANCELAR atividades.
A41: Para editar setores: SOBRESCREVA ou LIMPE as células (Delete). NÃO exclua linhas — isso quebra o menu suspenso.
A42: Se o menu suspenso quebrar mesmo assim, use GSL Bartofil > Reaplicar lista de setores.

Sheet JUL 2026
A1: 07 · JULHO 2026 | O1: GSL BARTOFIL
A3: =IF((COUNTIF($R$22:$R$210,"Aprovada")+COUNTIF($R$22:$R$210,"Entregue")+COUNTIF($R$22:$R$210,"Pendente")+COUNTIF($R$22:$R$210,"Atrasada")+COUNTIF($R$22:$R$210,"Reprovada"))=0,"",IF(COUNTIF($R$22:$R$210,"Aprovada")=(COUNTIF($R$22:$R$210,"Aprovada")+COUNTIF($R$22:$R$210,"Entregue")+COUNTIF($R$22:$R$210,"Pendente")+COUNTIF($R$22:$R$210,"Atrasada")+COUNTIF($R$22:$R$210,"Reprovada")),"MÊS CONCLUÍDO — todas as atividades aprovadas","EM ANDAMENTO — "&COUNTIF($R$22:$R$210,"Aprovada")&" de "&(COUNTIF($R$22:$R$210,"Aprovada")+COUNTIF($R$22:$R$210,"Entregue")+COUNTIF($R$22:$R$210,"Pendente")+COUNTIF($R$22:$R$210,"Atrasada")+COUNTIF($R$22:$R$210,"Reprovada"))&" atividades aprovadas"))
B5: DOM | D5: SEG | F5: TER | H5: QUA | J5: QUI | L5: SEX | N5: SÁB
H6: 46204 | J6: 46205 | L6: 46206 | N6: 46207
H7: =IF(H6="","",TRIM(IF(COUNTIFS($C$22:$C$210,H6,$D$22:$D$210,"*Erros*",$O$22:$O$210,"<>Cancelada")>0,"Erros ","")&IF(COUNTIFS($C$22:$C$210,H6,$D$22:$D$210,"*Suporte*",$O$22:$O$210,"<>Cancelada")>0,"Suporte ","")&IF(COUNTIFS($C$22:$C$210,H6,$D$22:$D$210,"*Vistoria*",$O$22:$O$210,"<>Cancelada")>0,"Vistoria ","")&IF(COUNTIFS($C$22:$C$210,H6,$D$22:$D$210,"*Metas*",$O$22:$O$210,"<>Cancelada")>0,"Metas ","")&IF(COUNTIFS($C$22:$C$210,H6,$D$22:$D$210,"*Faltas*",$O$22:$O$210,"<>Cancelada")>0,"Faltas ","")&IF(COUNTIFS($C$22:$C$210,H6,$D$22:$D$210,"*Semanal c/*",$O$22:$O$210,"<>Cancelada")>0,"Acomp. ","")&IF(COUNTIFS($C$22:$C$210,H6,$D$22:$D$210,"*Reunião*",$O$22:$O$210,"<>Cancelada")>0,"Reunião ","")&IF(COUNTIFS($C$22:$C$210,H6,$D$22:$D$210,"*Férias*",$O$22:$O$210,"<>Cancelada")>0,"Férias ","")&IF(COUNTIFS($C$22:$C$210,H6,$D$22:$D$210,"*Mudança*",$O$22:$O$210,"<>Cancelada")>0,"M.Função ","")&IF(COUNTIFS($C$22:$C$210,H6,$D$22:$D$210,"*Treinamento*",$O$22:$O$210,"<>Cancelada")>0,"Trein. ",""))) | J7: =IF(J6="","",TRIM(IF(COUNTIFS($C$22:$C$210,J6,$D$22:$D$210,"*Erros*",$O$22:$O$210,"<>Cancelada")>0,"Erros ","")&IF(COUNTIFS($C$22:$C$210,J6,$D$22:$D$210,"*Suporte*",$O$22:$O$210,"<>Cancelada")>0,"Suporte ","")&IF(COUNTIFS($C$22:$C$210,J6,$D$22:$D$210,"*Vistoria*",$O$22:$O$210,"<>Cancelada")>0,"Vistoria ","")&IF(COUNTIFS($C$22:$C$210,J6,$D$22:$D$210,"*Metas*",$O$22:$O$210,"<>Cancelada")>0,"Metas ","")&IF(COUNTIFS($C$22:$C$210,J6,$D$22:$D$210,"*Faltas*",$O$22:$O$210,"<>Cancelada")>0,"Faltas ","")&IF(COUNTIFS($C$22:$C$210,J6,$D$22:$D$210,"*Semanal c/*",$O$22:$O$210,"<>Cancelada")>0,"Acomp. ","")&IF(COUNTIFS($C$22:$C$210,J6,$D$22:$D$210,"*Reunião*",$O$22:$O$210,"<>Cancelada")>0,"Reunião ","")&IF(COUNTIFS($C$22:$C$210,J6,$D$22:$D$210,"*Férias*",$O$22:$O$210,"<>Cancelada")>0,"Férias ","")&IF(COUNTIFS($C$22:$C$210,J6,$D$22:$D$210,"*Mudança*",$O$22:$O$210,"<>Cancelada")>0,"M.Função ","")&IF(COUNTIFS($C$22:$C$210,J6,$D$22:$D$210,"*Treinamento*",$O$22:$O$210,"<>Cancelada")>0,"Trein. ",""))) | L7: =IF(L6="","",TRIM(IF(COUNTIFS($C$22:$C$210,L6,$D$22:$D$210,"*Erros*",$O$22:$O$210,"<>Cancelada")>0,"Erros ","")&IF(COUNTIFS($C$22:$C$210,L6,$D$22:$D$210,"*Suporte*",$O$22:$O$210,"<>Cancelada")>0,"Suporte ","")&IF(COUNTIFS($C$22:$C$210,L6,$D$22:$D$210,"*Vistoria*",$O$22:$O$210,"<>Cancelada")>0,"Vistoria ","")&IF(COUNTIFS($C$22:$C$210,L6,$D$22:$D$210,"*Metas*",$O$22:$O$210,"<>Cancelada")>0,"Metas ","")&IF(COUNTIFS($C$22:$C$210,L6,$D$22:$D$210,"*Faltas*",$O$22:$O$210,"<>Cancelada")>0,"Faltas ","")&IF(COUNTIFS($C$22:$C$210,L6,$D$22:$D$210,"*Semanal c/*",$O$22:$O$210,"<>Cancelada")>0,"Acomp. ","")&IF(COUNTIFS($C$22:$C$210,L6,$D$22:$D$210,"*Reunião*",$O$22:$O$210,"<>Cancelada")>0,"Reunião ","")&IF(COUNTIFS($C$22:$C$210,L6,$D$22:$D$210,"*Férias*",$O$22:$O$210,"<>Cancelada")>0,"Férias ","")&IF(COUNTIFS($C$22:$C$210,L6,$D$22:$D$210,"*Mudança*",$O$22:$O$210,"<>Cancelada")>0,"M.Função ","")&IF(COUNTIFS($C$22:$C$210,L6,$D$22:$D$210,"*Treinamento*",$O$22:$O$210,"<>Cancelada")>0,"Trein. ",""))) | N7: =IF(N6="","",TRIM(IF(COUNTIFS($C$22:$C$210,N6,$D$22:$D$210,"*Erros*",$O$22:$O$210,"<>Cancelada")>0,"Erros ","")&IF(COUNTIFS($C$22:$C$210,N6,$D$22:$D$210,"*Suporte*",$O$22:$O$210,"<>Cancelada")>0,"Suporte ","")&IF(COUNTIFS($C$22:$C$210,N6,$D$22:$D$210,"*Vistoria*",$O$22:$O$210,"<>Cancelada")>0,"Vistoria ","")&IF(COUNTIFS($C$22:$C$210,N6,$D$22:$D$210,"*Metas*",$O$22:$O$210,"<>Cancelada")>0,"Metas ","")&IF(COUNTIFS($C$22:$C$210,N6,$D$22:$D$210,"*Faltas*",$O$22:$O$210,"<>Cancelada")>0,"Faltas ","")&IF(COUNTIFS($C$22:$C$210,N6,$D$22:$D$210,"*Semanal c/*",$O$22:$O$210,"<>Cancelada")>0,"Acomp. ","")&IF(COUNTIFS($C$22:$C$210,N6,$D$22:$D$210,"*Reunião*",$O$22:$O$210,"<>Cancelada")>0,"Reunião ","")&IF(COUNTIFS($C$22:$C$210,N6,$D$22:$D$210,"*Férias*",$O$22:$O$210,"<>Cancelada")>0,"Férias ","")&IF(COUNTIFS($C$22:$C$210,N6,$D$22:$D$210,"*Mudança*",$O$22:$O$210,"<>Cancelada")>0,"M.Função ","")&IF(COUNTIFS($C$22:$C$210,N6,$D$22:$D$210,"*Treinamento*",$O$22:$O$210,"<>Cancelada")>0,"Trein. ","")))
B8: 46208 | D8: 46209 | F8: 46210 | H8: 46211 | J8: 46212 | L8: 46213 | N8: 46214
B9: =IF(B8="","",TRIM(IF(COUNTIFS($C$22:$C$210,B8,$D$22:$D$210,"*Erros*",$O$22:$O$210,"<>Cancelada")>0,"Erros ","")&IF(COUNTIFS($C$22:$C$210,B8,$D$22:$D$210,"*Suporte*",$O$22:$O$210,"<>Cancelada")>0,"Suporte ","")&IF(COUNTIFS($C$22:$C$210,B8,$D$22:$D$210,"*Vistoria*",$O$22:$O$210,"<>Cancelada")>0,"Vistoria ","")&IF(COUNTIFS($C$22:$C$210,B8,$D$22:$D$210,"*Metas*",$O$22:$O$210,"<>Cancelada")>0,"Metas ","")&IF(COUNTIFS($C$22:$C$210,B8,$D$22:$D$210,"*Faltas*",$O$22:$O$210,"<>Cancelada")>0,"Faltas ","")&IF(COUNTIFS($C$22:$C$210,B8,$D$22:$D$210,"*Semanal c/*",$O$22:$O$210,"<>Cancelada")>0,"Acomp. ","")&IF(COUNTIFS($C$22:$C$210,B8,$D$22:$D$210,"*Reunião*",$O$22:$O$210,"<>Cancelada")>0,"Reunião ","")&IF(COUNTIFS($C$22:$C$210,B8,$D$22:$D$210,"*Férias*",$O$22:$O$210,"<>Cancelada")>0,"Férias ","")&IF(COUNTIFS($C$22:$C$210,B8,$D$22:$D$210,"*Mudança*",$O$22:$O$210,"<>Cancelada")>0,"M.Função ","")&IF(COUNTIFS($C$22:$C$210,B8,$D$22:$D$210,"*Treinamento*",$O$22:$O$210,"<>Cancelada")>0,"Trein. ",""))) | D9: =IF(D8="","",TRIM(IF(COUNTIFS($C$22:$C$210,D8,$D$22:$D$210,"*Erros*",$O$22:$O$210,"<>Cancelada")>0,"Erros ","")&IF(COUNTIFS($C$22:$C$210,D8,$D$22:$D$210,"*Suporte*",$O$22:$O$210,"<>Cancelada")>0,"Suporte ","")&IF(COUNTIFS($C$22:$C$210,D8,$D$22:$D$210,"*Vistoria*",$O$22:$O$210,"<>Cancelada")>0,"Vistoria ","")&IF(COUNTIFS($C$22:$C$210,D8,$D$22:$D$210,"*Metas*",$O$22:$O$210,"<>Cancelada")>0,"Metas ","")&IF(COUNTIFS($C$22:$C$210,D8,$D$22:$D$210,"*Faltas*",$O$22:$O$210,"<>Cancelada")>0,"Faltas ","")&IF(COUNTIFS($C$22:$C$210,D8,$D$22:$D$210,"*Semanal c/*",$O$22:$O$210,"<>Cancelada")>0,"Acomp. ","")&IF(COUNTIFS($C$22:$C$210,D8,$D$22:$D$210,"*Reunião*",$O$22:$O$210,"<>Cancelada")>0,"Reunião ","")&IF(COUNTIFS($C$22:$C$210,D8,$D$22:$D$210,"*Férias*",$O$22:$O$210,"<>Cancelada")>0,"Férias ","")&IF(COUNTIFS($C$22:$C$210,D8,$D$22:$D$210,"*Mudança*",$O$22:$O$210,"<>Cancelada")>0,"M.Função ","")&IF(COUNTIFS($C$22:$C$210,D8,$D$22:$D$210,"*Treinamento*",$O$22:$O$210,"<>Cancelada")>0,"Trein. ",""))) | F9: =IF(F8="","",TRIM(IF(COUNTIFS($C$22:$C$210,F8,$D$22:$D$210,"*Erros*",$O$22:$O$210,"<>Cancelada")>0,"Erros ","")&IF(COUNTIFS($C$22:$C$210,F8,$D$22:$D$210,"*Suporte*",$O$22:$O$210,"<>Cancelada")>0,"Suporte ","")&IF(COUNTIFS($C$22:$C$210,F8,$D$22:$D$210,"*Vistoria*",$O$22:$O$210,"<>Cancelada")>0,"Vistoria ","")&IF(COUNTIFS($C$22:$C$210,F8,$D$22:$D$210,"*Metas*",$O$22:$O$210,"<>Cancelada")>0,"Metas ","")&IF(COUNTIFS($C$22:$C$210,F8,$D$22:$D$210,"*Faltas*",$O$22:$O$210,"<>Cancelada")>0,"Faltas ","")&IF(COUNTIFS($C$22:$C$210,F8,$D$22:$D$210,"*Semanal c/*",$O$22:$O$210,"<>Cancelada")>0,"Acomp. ","")&IF(COUNTIFS($C$22:$C$210,F8,$D$22:$D$210,"*Reunião*",$O$22:$O$210,"<>Cancelada")>0,"Reunião ","")&IF(COUNTIFS($C$22:$C$210,F8,$D$22:$D$210,"*Férias*",$O$22:$O$210,"<>Cancelada")>0,"Férias ","")&IF(COUNTIFS($C$22:$C$210,F8,$D$22:$D$210,"*Mudança*",$O$22:$O$210,"<>Cancelada")>0,"M.Função ","")&IF(COUNTIFS($C$22:$C$210,F8,$D$22:$D$210,"*Treinamento*",$O$22:$O$210,"<>Cancelada")>0,"Trein. ",""))) | H9: =IF(H8="","",TRIM(IF(COUNTIFS($C$22:$C$210,H8,$D$22:$D$210,"*Erros*",$O$22:$O$210,"<>Cancelada")>0,"Erros ","")&IF(COUNTIFS($C$22:$C$210,H8,$D$22:$D$210,"*Suporte*",$O$22:$O$210,"<>Cancelada")>0,"Suporte ","")&IF(COUNTIFS($C$22:$C$210,H8,$D$22:$D$210,"*Vistoria*",$O$22:$O$210,"<>Cancelada")>0,"Vistoria ","")&IF(COUNTIFS($C$22:$C$210,H8,$D$22:$D$210,"*Metas*",$O$22:$O$210,"<>Cancelada")>0,"Metas ","")&IF(COUNTIFS($C$22:$C$210,H8,$D$22:$D$210,"*Faltas*",$O$22:$O$210,"<>Cancelada")>0,"Faltas ","")&IF(COUNTIFS($C$22:$C$210,H8,$D$22:$D$210,"*Semanal c/*",$O$22:$O$210,"<>Cancelada")>0,"Acomp. ","")&IF(COUNTIFS($C$22:$C$210,H8,$D$22:$D$210,"*Reunião*",$O$22:$O$210,"<>Cancelada")>0,"Reunião ","")&IF(COUNTIFS($C$22:$C$210,H8,$D$22:$D$210,"*Férias*",$O$22:$O$210,"<>Cancelada")>0,"Férias ","")&IF(COUNTIFS($C$22:$C$210,H8,$D$22:$D$210,"*Mudança*",$O$22:$O$210,"<>Cancelada")>0,"M.Função ","")&IF(COUNTIFS($C$22:$C$210,H8,$D$22:$D$210,"*Treinamento*",$O$22:$O$210,"<>Cancelada")>0,"Trein. ",""))) | J9: =IF(J8="","",TRIM(IF(COUNTIFS($C$22:$C$210,J8,$D$22:$D$210,"*Erros*",$O$22:$O$210,"<>Cancelada")>0,"Erros ","")&IF(COUNTIFS($C$22:$C$210,J8,$D$22:$D$210,"*Suporte*",$O$22:$O$210,"<>Cancelada")>0,"Suporte ","")&IF(COUNTIFS($C$22:$C$210,J8,$D$22:$D$210,"*Vistoria*",$O$22:$O$210,"<>Cancelada")>0,"Vistoria ","")&IF(COUNTIFS($C$22:$C$210,J8,$D$22:$D$210,"*Metas*",$O$22:$O$210,"<>Cancelada")>0,"Metas ","")&IF(COUNTIFS($C$22:$C$210,J8,$D$22:$D$210,"*Faltas*",$O$22:$O$210,"<>Cancelada")>0,"Faltas ","")&IF(COUNTIFS($C$22:$C$210,J8,$D$22:$D$210,"*Semanal c/*",$O$22:$O$210,"<>Cancelada")>0,"Acomp. ","")&IF(COUNTIFS($C$22:$C$210,J8,$D$22:$D$210,"*Reunião*",$O$22:$O$210,"<>Cancelada")>0,"Reunião ","")&IF(COUNTIFS($C$22:$C$210,J8,$D$22:$D$210,"*Férias*",$O$22:$O$210,"<>Cancelada")>0,"Férias ","")&IF(COUNTIFS($C$22:$C$210,J8,$D$22:$D$210,"*Mudança*",$O$22:$O$210,"<>Cancelada")>0,"M.Função ","")&IF(COUNTIFS($C$22:$C$210,J8,$D$22:$D$210,"*Treinamento*",$O$22:$O$210,"<>Cancelada")>0,"Trein. ",""))) | L9: =IF(L8="","",TRIM(IF(COUNTIFS($C$22:$C$210,L8,$D$22:$D$210,"*Erros*",$O$22:$O$210,"<>Cancelada")>0,"Erros ","")&IF(COUNTIFS($C$22:$C$210,L8,$D$22:$D$210,"*Suporte*",$O$22:$O$210,"<>Cancelada")>0,"Suporte ","")&IF(COUNTIFS($C$22:$C$210,L8,$D$22:$D$210,"*Vistoria*",$O$22:$O$210,"<>Cancelada")>0,"Vistoria ","")&IF(COUNTIFS($C$22:$C$210,L8,$D$22:$D$210,"*Metas*",$O$22:$O$210,"<>Cancelada")>0,"Metas ","")&IF(COUNTIFS($C$22:$C$210,L8,$D$22:$D$210,"*Faltas*",$O$22:$O$210,"<>Cancelada")>0,"Faltas ","")&IF(COUNTIFS($C$22:$C$210,L8,$D$22:$D$210,"*Semanal c/*",$O$22:$O$210,"<>Cancelada")>0,"Acomp. ","")&IF(COUNTIFS($C$22:$C$210,L8,$D$22:$D$210,"*Reunião*",$O$22:$O$210,"<>Cancelada")>0,"Reunião ","")&IF(COUNTIFS($C$22:$C$210,L8,$D$22:$D$210,"*Férias*",$O$22:$O$210,"<>Cancelada")>0,"Férias ","")&IF(COUNTIFS($C$22:$C$210,L8,$D$22:$D$210,"*Mudança*",$O$22:$O$210,"<>Cancelada")>0,"M.Função ","")&IF(COUNTIFS($C$22:$C$210,L8,$D$22:$D$210,"*Treinamento*",$O$22:$O$210,"<>Cancelada")>0,"Trein. ",""))) | N9: =IF(N8="","",TRIM(IF(COUNTIFS($C$22:$C$210,N8,$D$22:$D$210,"*Erros*",$O$22:$O$210,"<>Cancelada")>0,"Erros ","")&IF(COUNTIFS($C$22:$C$210,N8,$D$22:$D$210,"*Suporte*",$O$22:$O$210,"<>Cancelada")>0,"Suporte ","")&IF(COUNTIFS($C$22:$C$210,N8,$D$22:$D$210,"*Vistoria*",$O$22:$O$210,"<>Cancelada")>0,"Vistoria ","")&IF(COUNTIFS($C$22:$C$210,N8,$D$22:$D$210,"*Metas*",$O$22:$O$210,"<>Cancelada")>0,"Metas ","")&IF(COUNTIFS($C$22:$C$210,N8,$D$22:$D$210,"*Faltas*",$O$22:$O$210,"<>Cancelada")>0,"Faltas ","")&IF(COUNTIFS($C$22:$C$210,N8,$D$22:$D$210,"*Semanal c/*",$O$22:$O$210,"<>Cancelada")>0,"Acomp. ","")&IF(COUNTIFS($C$22:$C$210,N8,$D$22:$D$210,"*Reunião*",$O$22:$O$210,"<>Cancelada")>0,"Reunião ","")&IF(COUNTIFS($C$22:$C$210,N8,$D$22:$D$210,"*Férias*",$O$22:$O$210,"<>Cancelada")>0,"Férias ","")&IF(COUNTIFS($C$22:$C$210,N8,$D$22:$D$210,"*Mudança*",$O$22:$O$210,"<>Cancelada")>0,"M.Função ","")&IF(COUNTIFS($C$22:$C$210,N8,$D$22:$D$210,"*Treinamento*",$O$22:$O$210,"<>Cancelada")>0,"Trein. ","")))
B10: 46215 | D10: 46216 | F10: 46217 | H10: 46218 | J10: 46219 | L10: 46220 | N10: 46221
B11: =IF(B10="","",TRIM(IF(COUNTIFS($C$22:$C$210,B10,$D$22:$D$210,"*Erros*",$O$22:$O$210,"<>Cancelada")>0,"Erros ","")&IF(COUNTIFS($C$22:$C$210,B10,$D$22:$D$210,"*Suporte*",$O$22:$O$210,"<>Cancelada")>0,"Suporte ","")&IF(COUNTIFS($C$22:$C$210,B10,$D$22:$D$210,"*Vistoria*",$O$22:$O$210,"<>Cancelada")>0,"Vistoria ","")&IF(COUNTIFS($C$22:$C$210,B10,$D$22:$D$210,"*Metas*",$O$22:$O$210,"<>Cancelada")>0,"Metas ","")&IF(COUNTIFS($C$22:$C$210,B10,$D$22:$D$210,"*Faltas*",$O$22:$O$210,"<>Cancelada")>0,"Faltas ","")&IF(COUNTIFS($C$22:$C$210,B10,$D$22:$D$210,"*Semanal c/*",$O$22:$O$210,"<>Cancelada")>0,"Acomp. ","")&IF(COUNTIFS($C$22:$C$210,B10,$D$22:$D$210,"*Reunião*",$O$22:$O$210,"<>Cancelada")>0,"Reunião ","")&IF(COUNTIFS($C$22:$C$210,B10,$D$22:$D$210,"*Férias*",$O$22:$O$210,"<>Cancelada")>0,"Férias ","")&IF(COUNTIFS($C$22:$C$210,B10,$D$22:$D$210,"*Mudança*",$O$22:$O$210,"<>Cancelada")>0,"M.Função ","")&IF(COUNTIFS($C$22:$C$210,B10,$D$22:$D$210,"*Treinamento*",$O$22:$O$210,"<>Cancelada")>0,"Trein. ",""))) | D11: =IF(D10="","",TRIM(IF(COUNTIFS($C$22:$C$210,D10,$D$22:$D$210,"*Erros*",$O$22:$O$210,"<>Cancelada")>0,"Erros ","")&IF(COUNTIFS($C$22:$C$210,D10,$D$22:$D$210,"*Suporte*",$O$22:$O$210,"<>Cancelada")>0,"Suporte ","")&IF(COUNTIFS($C$22:$C$210,D10,$D$22:$D$210,"*Vistoria*",$O$22:$O$210,"<>Cancelada")>0,"Vistoria ","")&IF(COUNTIFS($C$22:$C$210,D10,$D$22:$D$210,"*Metas*",$O$22:$O$210,"<>Cancelada")>0,"Metas ","")&IF(COUNTIFS($C$22:$C$210,D10,$D$22:$D$210,"*Faltas*",$O$22:$O$210,"<>Cancelada")>0,"Faltas ","")&IF(COUNTIFS($C$22:$C$210,D10,$D$22:$D$210,"*Semanal c/*",$O$22:$O$210,"<>Cancelada")>0,"Acomp. ","")&IF(COUNTIFS($C$22:$C$210,D10,$D$22:$D$210,"*Reunião*",$O$22:$O$210,"<>Cancelada")>0,"Reunião ","")&IF(COUNTIFS($C$22:$C$210,D10,$D$22:$D$210,"*Férias*",$O$22:$O$210,"<>Cancelada")>0,"Férias ","")&IF(COUNTIFS($C$22:$C$210,D10,$D$22:$D$210,"*Mudança*",$O$22:$O$210,"<>Cancelada")>0,"M.Função ","")&IF(COUNTIFS($C$22:$C$210,D10,$D$22:$D$210,"*Treinamento*",$O$22:$O$210,"<>Cancelada")>0,"Trein. ",""))) | F11: =IF(F10="","",TRIM(IF(COUNTIFS($C$22:$C$210,F10,$D$22:$D$210,"*Erros*",$O$22:$O$210,"<>Cancelada")>0,"Erros ","")&IF(COUNTIFS($C$22:$C$210,F10,$D$22:$D$210,"*Suporte*",$O$22:$O$210,"<>Cancelada")>0,"Suporte ","")&IF(COUNTIFS($C$22:$C$210,F10,$D$22:$D$210,"*Vistoria*",$O$22:$O$210,"<>Cancelada")>0,"Vistoria ","")&IF(COUNTIFS($C$22:$C$210,F10,$D$22:$D$210,"*Metas*",$O$22:$O$210,"<>Cancelada")>0,"Metas ","")&IF(COUNTIFS($C$22:$C$210,F10,$D$22:$D$210,"*Faltas*",$O$22:$O$210,"<>Cancelada")>0,"Faltas ","")&IF(COUNTIFS($C$22:$C$210,F10,$D$22:$D$210,"*Semanal c/*",$O$22:$O$210,"<>Cancelada")>0,"Acomp. ","")&IF(COUNTIFS($C$22:$C$210,F10,$D$22:$D$210,"*Reunião*",$O$22:$O$210,"<>Cancelada")>0,"Reunião ","")&IF(COUNTIFS($C$22:$C$210,F10,$D$22:$D$210,"*Férias*",$O$22:$O$210,"<>Cancelada")>0,"Férias ","")&IF(COUNTIFS($C$22:$C$210,F10,$D$22:$D$210,"*Mudança*",$O$22:$O$210,"<>Cancelada")>0,"M.Função ","")&IF(COUNTIFS($C$22:$C$210,F10,$D$22:$D$210,"*Treinamento*",$O$22:$O$210,"<>Cancelada")>0,"Trein. ",""))) | H11: =IF(H10="","",TRIM(IF(COUNTIFS($C$22:$C$210,H10,$D$22:$D$210,"*Erros*",$O$22:$O$210,"<>Cancelada")>0,"Erros ","")&IF(COUNTIFS($C$22:$C$210,H10,$D$22:$D$210,"*Suporte*",$O$22:$O$210,"<>Cancelada")>0,"Suporte ","")&IF(COUNTIFS($C$22:$C$210,H10,$D$22:$D$210,"*Vistoria*",$O$22:$O$210,"<>Cancelada")>0,"Vistoria ","")&IF(COUNTIFS($C$22:$C$210,H10,$D$22:$D$210,"*Metas*",$O$22:$O$210,"<>Cancelada")>0,"Metas ","")&IF(COUNTIFS($C$22:$C$210,H10,$D$22:$D$210,"*Faltas*",$O$22:$O$210,"<>Cancelada")>0,"Faltas ","")&IF(COUNTIFS($C$22:$C$210,H10,$D$22:$D$210,"*Semanal c/*",$O$22:$O$210,"<>Cancelada")>0,"Acomp. ","")&IF(COUNTIFS($C$22:$C$210,H10,$D$22:$D$210,"*Reunião*",$O$22:$O$210,"<>Cancelada")>0,"Reunião ","")&IF(COUNTIFS($C$22:$C$210,H10,$D$22:$D$210,"*Férias*",$O$22:$O$210,"<>Cancelada")>0,"Férias ","")&IF(COUNTIFS($C$22:$C$210,H10,$D$22:$D$210,"*Mudança*",$O$22:$O$210,"<>Cancelada")>0,"M.Função ","")&IF(COUNTIFS($C$22:$C$210,H10,$D$22:$D$210,"*Treinamento*",$O$22:$O$210,"<>Cancelada")>0,"Trein. ",""))) | J11: =IF(J10="","",TRIM(IF(COUNTIFS($C$22:$C$210,J10,$D$22:$D$210,"*Erros*",$O$22:$O$210,"<>Cancelada")>0,"Erros ","")&IF(COUNTIFS($C$22:$C$210,J10,$D$22:$D$210,"*Suporte*",$O$22:$O$210,"<>Cancelada")>0,"Suporte ","")&IF(COUNTIFS($C$22:$C$210,J10,$D$22:$D$210,"*Vistoria*",$O$22:$O$210,"<>Cancelada")>0,"Vistoria ","")&IF(COUNTIFS($C$22:$C$210,J10,$D$22:$D$210,"*Metas*",$O$22:$O$210,"<>Cancelada")>0,"Metas ","")&IF(COUNTIFS($C$22:$C$210,J10,$D$22:$D$210,"*Faltas*",$O$22:$O$210,"<>Cancelada")>0,"Faltas ","")&IF(COUNTIFS($C$22:$C$210,J10,$D$22:$D$210,"*Semanal c/*",$O$22:$O$210,"<>Cancelada")>0,"Acomp. ","")&IF(COUNTIFS($C$22:$C$210,J10,$D$22:$D$210,"*Reunião*",$O$22:$O$210,"<>Cancelada")>0,"Reunião ","")&IF(COUNTIFS($C$22:$C$210,J10,$D$22:$D$210,"*Férias*",$O$22:$O$210,"<>Cancelada")>0,"Férias ","")&IF(COUNTIFS($C$22:$C$210,J10,$D$22:$D$210,"*Mudança*",$O$22:$O$210,"<>Cancelada")>0,"M.Função ","")&IF(COUNTIFS($C$22:$C$210,J10,$D$22:$D$210,"*Treinamento*",$O$22:$O$210,"<>Cancelada")>0,"Trein. ",""))) | L11: =IF(L10="","",TRIM(IF(COUNTIFS($C$22:$C$210,L10,$D$22:$D$210,"*Erros*",$O$22:$O$210,"<>Cancelada")>0,"Erros ","")&IF(COUNTIFS($C$22:$C$210,L10,$D$22:$D$210,"*Suporte*",$O$22:$O$210,"<>Cancelada")>0,"Suporte ","")&IF(COUNTIFS($C$22:$C$210,L10,$D$22:$D$210,"*Vistoria*",$O$22:$O$210,"<>Cancelada")>0,"Vistoria ","")&IF(COUNTIFS($C$22:$C$210,L10,$D$22:$D$210,"*Metas*",$O$22:$O$210,"<>Cancelada")>0,"Metas ","")&IF(COUNTIFS($C$22:$C$210,L10,$D$22:$D$210,"*Faltas*",$O$22:$O$210,"<>Cancelada")>0,"Faltas ","")&IF(COUNTIFS($C$22:$C$210,L10,$D$22:$D$210,"*Semanal c/*",$O$22:$O$210,"<>Cancelada")>0,"Acomp. ","")&IF(COUNTIFS($C$22:$C$210,L10,$D$22:$D$210,"*Reunião*",$O$22:$O$210,"<>Cancelada")>0,"Reunião ","")&IF(COUNTIFS($C$22:$C$210,L10,$D$22:$D$210,"*Férias*",$O$22:$O$210,"<>Cancelada")>0,"Férias ","")&IF(COUNTIFS($C$22:$C$210,L10,$D$22:$D$210,"*Mudança*",$O$22:$O$210,"<>Cancelada")>0,"M.Função ","")&IF(COUNTIFS($C$22:$C$210,L10,$D$22:$D$210,"*Treinamento*",$O$22:$O$210,"<>Cancelada")>0,"Trein. ",""))) | N11: =IF(N10="","",TRIM(IF(COUNTIFS($C$22:$C$210,N10,$D$22:$D$210,"*Erros*",$O$22:$O$210,"<>Cancelada")>0,"Erros ","")&IF(COUNTIFS($C$22:$C$210,N10,$D$22:$D$210,"*Suporte*",$O$22:$O$210,"<>Cancelada")>0,"Suporte ","")&IF(COUNTIFS($C$22:$C$210,N10,$D$22:$D$210,"*Vistoria*",$O$22:$O$210,"<>Cancelada")>0,"Vistoria ","")&IF(COUNTIFS($C$22:$C$210,N10,$D$22:$D$210,"*Metas*",$O$22:$O$210,"<>Cancelada")>0,"Metas ","")&IF(COUNTIFS($C$22:$C$210,N10,$D$22:$D$210,"*Faltas*",$O$22:$O$210,"<>Cancelada")>0,"Faltas ","")&IF(COUNTIFS($C$22:$C$210,N10,$D$22:$D$210,"*Semanal c/*",$O$22:$O$210,"<>Cancelada")>0,"Acomp. ","")&IF(COUNTIFS($C$22:$C$210,N10,$D$22:$D$210,"*Reunião*",$O$22:$O$210,"<>Cancelada")>0,"Reunião ","")&IF(COUNTIFS($C$22:$C$210,N10,$D$22:$D$210,"*Férias*",$O$22:$O$210,"<>Cancelada")>0,"Férias ","")&IF(COUNTIFS($C$22:$C$210,N10,$D$22:$D$210,"*Mudança*",$O$22:$O$210,"<>Cancelada")>0,"M.Função ","")&IF(COUNTIFS($C$22:$C$210,N10,$D$22:$D$210,"*Treinamento*",$O$22:$O$210,"<>Cancelada")>0,"Trein. ","")))
B12: 46222 | D12: 46223 | F12: 46224 | H12: 46225 | J12: 46226 | L12: 46227 | N12: 46228
B13: =IF(B12="","",TRIM(IF(COUNTIFS($C$22:$C$210,B12,$D$22:$D$210,"*Erros*",$O$22:$O$210,"<>Cancelada")>0,"Erros ","")&IF(COUNTIFS($C$22:$C$210,B12,$D$22:$D$210,"*Suporte*",$O$22:$O$210,"<>Cancelada")>0,"Suporte ","")&IF(COUNTIFS($C$22:$C$210,B12,$D$22:$D$210,"*Vistoria*",$O$22:$O$210,"<>Cancelada")>0,"Vistoria ","")&IF(COUNTIFS($C$22:$C$210,B12,$D$22:$D$210,"*Metas*",$O$22:$O$210,"<>Cancelada")>0,"Metas ","")&IF(COUNTIFS($C$22:$C$210,B12,$D$22:$D$210,"*Faltas*",$O$22:$O$210,"<>Cancelada")>0,"Faltas ","")&IF(COUNTIFS($C$22:$C$210,B12,$D$22:$D$210,"*Semanal c/*",$O$22:$O$210,"<>Cancelada")>0,"Acomp. ","")&IF(COUNTIFS($C$22:$C$210,B12,$D$22:$D$210,"*Reunião*",$O$22:$O$210,"<>Cancelada")>0,"Reunião ","")&IF(COUNTIFS($C$22:$C$210,B12,$D$22:$D$210,"*Férias*",$O$22:$O$210,"<>Cancelada")>0,"Férias ","")&IF(COUNTIFS($C$22:$C$210,B12,$D$22:$D$210,"*Mudança*",$O$22:$O$210,"<>Cancelada")>0,"M.Função ","")&IF(COUNTIFS($C$22:$C$210,B12,$D$22:$D$210,"*Treinamento*",$O$22:$O$210,"<>Cancelada")>0,"Trein. ",""))) | D13: =IF(D12="","",TRIM(IF(COUNTIFS($C$22:$C$210,D12,$D$22:$D$210,"*Erros*",$O$22:$O$210,"<>Cancelada")>0,"Erros ","")&IF(COUNTIFS($C$22:$C$210,D12,$D$22:$D$210,"*Suporte*",$O$22:$O$210,"<>Cancelada")>0,"Suporte ","")&IF(COUNTIFS($C$22:$C$210,D12,$D$22:$D$210,"*Vistoria*",$O$22:$O$210,"<>Cancelada")>0,"Vistoria ","")&IF(COUNTIFS($C$22:$C$210,D12,$D$22:$D$210,"*Metas*",$O$22:$O$210,"<>Cancelada")>0,"Metas ","")&IF(COUNTIFS($C$22:$C$210,D12,$D$22:$D$210,"*Faltas*",$O$22:$O$210,"<>Cancelada")>0,"Faltas ","")&IF(COUNTIFS($C$22:$C$210,D12,$D$22:$D$210,"*Semanal c/*",$O$22:$O$210,"<>Cancelada")>0,"Acomp. ","")&IF(COUNTIFS($C$22:$C$210,D12,$D$22:$D$210,"*Reunião*",$O$22:$O$210,"<>Cancelada")>0,"Reunião ","")&IF(COUNTIFS($C$22:$C$210,D12,$D$22:$D$210,"*Férias*",$O$22:$O$210,"<>Cancelada")>0,"Férias ","")&IF(COUNTIFS($C$22:$C$210,D12,$D$22:$D$210,"*Mudança*",$O$22:$O$210,"<>Cancelada")>0,"M.Função ","")&IF(COUNTIFS($C$22:$C$210,D12,$D$22:$D$210,"*Treinamento*",$O$22:$O$210,"<>Cancelada")>0,"Trein. ",""))) | F13: =IF(F12="","",TRIM(IF(COUNTIFS($C$22:$C$210,F12,$D$22:$D$210,"*Erros*",$O$22:$O$210,"<>Cancelada")>0,"Erros ","")&IF(COUNTIFS($C$22:$C$210,F12,$D$22:$D$210,"*Suporte*",$O$22:$O$210,"<>Cancelada")>0,"Suporte ","")&IF(COUNTIFS($C$22:$C$210,F12,$D$22:$D$210,"*Vistoria*",$O$22:$O$210,"<>Cancelada")>0,"Vistoria ","")&IF(COUNTIFS($C$22:$C$210,F12,$D$22:$D$210,"*Metas*",$O$22:$O$210,"<>Cancelada")>0,"Metas ","")&IF(COUNTIFS($C$22:$C$210,F12,$D$22:$D$210,"*Faltas*",$O$22:$O$210,"<>Cancelada")>0,"Faltas ","")&IF(COUNTIFS($C$22:$C$210,F12,$D$22:$D$210,"*Semanal c/*",$O$22:$O$210,"<>Cancelada")>0,"Acomp. ","")&IF(COUNTIFS($C$22:$C$210,F12,$D$22:$D$210,"*Reunião*",$O$22:$O$210,"<>Cancelada")>0,"Reunião ","")&IF(COUNTIFS($C$22:$C$210,F12,$D$22:$D$210,"*Férias*",$O$22:$O$210,"<>Cancelada")>0,"Férias ","")&IF(COUNTIFS($C$22:$C$210,F12,$D$22:$D$210,"*Mudança*",$O$22:$O$210,"<>Cancelada")>0,"M.Função ","")&IF(COUNTIFS($C$22:$C$210,F12,$D$22:$D$210,"*Treinamento*",$O$22:$O$210,"<>Cancelada")>0,"Trein. ",""))) | H13: =IF(H12="","",TRIM(IF(COUNTIFS($C$22:$C$210,H12,$D$22:$D$210,"*Erros*",$O$22:$O$210,"<>Cancelada")>0,"Erros ","")&IF(COUNTIFS($C$22:$C$210,H12,$D$22:$D$210,"*Suporte*",$O$22:$O$210,"<>Cancelada")>0,"Suporte ","")&IF(COUNTIFS($C$22:$C$210,H12,$D$22:$D$210,"*Vistoria*",$O$22:$O$210,"<>Cancelada")>0,"Vistoria ","")&IF(COUNTIFS($C$22:$C$210,H12,$D$22:$D$210,"*Metas*",$O$22:$O$210,"<>Cancelada")>0,"Metas ","")&IF(COUNTIFS($C$22:$C$210,H12,$D$22:$D$210,"*Faltas*",$O$22:$O$210,"<>Cancelada")>0,"Faltas ","")&IF(COUNTIFS($C$22:$C$210,H12,$D$22:$D$210,"*Semanal c/*",$O$22:$O$210,"<>Cancelada")>0,"Acomp. ","")&IF(COUNTIFS($C$22:$C$210,H12,$D$22:$D$210,"*Reunião*",$O$22:$O$210,"<>Cancelada")>0,"Reunião ","")&IF(COUNTIFS($C$22:$C$210,H12,$D$22:$D$210,"*Férias*",$O$22:$O$210,"<>Cancelada")>0,"Férias ","")&IF(COUNTIFS($C$22:$C$210,H12,$D$22:$D$210,"*Mudança*",$O$22:$O$210,"<>Cancelada")>0,"M.Função ","")&IF(COUNTIFS($C$22:$C$210,H12,$D$22:$D$210,"*Treinamento*",$O$22:$O$210,"<>Cancelada")>0,"Trein. ",""))) | J13: =IF(J12="","",TRIM(IF(COUNTIFS($C$22:$C$210,J12,$D$22:$D$210,"*Erros*",$O$22:$O$210,"<>Cancelada")>0,"Erros ","")&IF(COUNTIFS($C$22:$C$210,J12,$D$22:$D$210,"*Suporte*",$O$22:$O$210,"<>Cancelada")>0,"Suporte ","")&IF(COUNTIFS($C$22:$C$210,J12,$D$22:$D$210,"*Vistoria*",$O$22:$O$210,"<>Cancelada")>0,"Vistoria ","")&IF(COUNTIFS($C$22:$C$210,J12,$D$22:$D$210,"*Metas*",$O$22:$O$210,"<>Cancelada")>0,"Metas ","")&IF(COUNTIFS($C$22:$C$210,J12,$D$22:$D$210,"*Faltas*",$O$22:$O$210,"<>Cancelada")>0,"Faltas ","")&IF(COUNTIFS($C$22:$C$210,J12,$D$22:$D$210,"*Semanal c/*",$O$22:$O$210,"<>Cancelada")>0,"Acomp. ","")&IF(COUNTIFS($C$22:$C$210,J12,$D$22:$D$210,"*Reunião*",$O$22:$O$210,"<>Cancelada")>0,"Reunião ","")&IF(COUNTIFS($C$22:$C$210,J12,$D$22:$D$210,"*Férias*",$O$22:$O$210,"<>Cancelada")>0,"Férias ","")&IF(COUNTIFS($C$22:$C$210,J12,$D$22:$D$210,"*Mudança*",$O$22:$O$210,"<>Cancelada")>0,"M.Função ","")&IF(COUNTIFS($C$22:$C$210,J12,$D$22:$D$210,"*Treinamento*",$O$22:$O$210,"<>Cancelada")>0,"Trein. ",""))) | L13: =IF(L12="","",TRIM(IF(COUNTIFS($C$22:$C$210,L12,$D$22:$D$210,"*Erros*",$O$22:$O$210,"<>Cancelada")>0,"Erros ","")&IF(COUNTIFS($C$22:$C$210,L12,$D$22:$D$210,"*Suporte*",$O$22:$O$210,"<>Cancelada")>0,"Suporte ","")&IF(COUNTIFS($C$22:$C$210,L12,$D$22:$D$210,"*Vistoria*",$O$22:$O$210,"<>Cancelada")>0,"Vistoria ","")&IF(COUNTIFS($C$22:$C$210,L12,$D$22:$D$210,"*Metas*",$O$22:$O$210,"<>Cancelada")>0,"Metas ","")&IF(COUNTIFS($C$22:$C$210,L12,$D$22:$D$210,"*Faltas*",$O$22:$O$210,"<>Cancelada")>0,"Faltas ","")&IF(COUNTIFS($C$22:$C$210,L12,$D$22:$D$210,"*Semanal c/*",$O$22:$O$210,"<>Cancelada")>0,"Acomp. ","")&IF(COUNTIFS($C$22:$C$210,L12,$D$22:$D$210,"*Reunião*",$O$22:$O$210,"<>Cancelada")>0,"Reunião ","")&IF(COUNTIFS($C$22:$C$210,L12,$D$22:$D$210,"*Férias*",$O$22:$O$210,"<>Cancelada")>0,"Férias ","")&IF(COUNTIFS($C$22:$C$210,L12,$D$22:$D$210,"*Mudança*",$O$22:$O$210,"<>Cancelada")>0,"M.Função ","")&IF(COUNTIFS($C$22:$C$210,L12,$D$22:$D$210,"*Treinamento*",$O$22:$O$210,"<>Cancelada")>0,"Trein. ",""))) | N13: =IF(N12="","",TRIM(IF(COUNTIFS($C$22:$C$210,N12,$D$22:$D$210,"*Erros*",$O$22:$O$210,"<>Cancelada")>0,"Erros ","")&IF(COUNTIFS($C$22:$C$210,N12,$D$22:$D$210,"*Suporte*",$O$22:$O$210,"<>Cancelada")>0,"Suporte ","")&IF(COUNTIFS($C$22:$C$210,N12,$D$22:$D$210,"*Vistoria*",$O$22:$O$210,"<>Cancelada")>0,"Vistoria ","")&IF(COUNTIFS($C$22:$C$210,N12,$D$22:$D$210,"*Metas*",$O$22:$O$210,"<>Cancelada")>0,"Metas ","")&IF(COUNTIFS($C$22:$C$210,N12,$D$22:$D$210,"*Faltas*",$O$22:$O$210,"<>Cancelada")>0,"Faltas ","")&IF(COUNTIFS($C$22:$C$210,N12,$D$22:$D$210,"*Semanal c/*",$O$22:$O$210,"<>Cancelada")>0,"Acomp. ","")&IF(COUNTIFS($C$22:$C$210,N12,$D$22:$D$210,"*Reunião*",$O$22:$O$210,"<>Cancelada")>0,"Reunião ","")&IF(COUNTIFS($C$22:$C$210,N12,$D$22:$D$210,"*Férias*",$O$22:$O$210,"<>Cancelada")>0,"Férias ","")&IF(COUNTIFS($C$22:$C$210,N12,$D$22:$D$210,"*Mudança*",$O$22:$O$210,"<>Cancelada")>0,"M.Função ","")&IF(COUNTIFS($C$22:$C$210,N12,$D$22:$D$210,"*Treinamento*",$O$22:$O$210,"<>Cancelada")>0,"Trein. ","")))
B14: 46229 | D14: 46230 | F14: 46231 | H14: 46232 | J14: 46233 | L14: 46234
B15: =IF(B14="","",TRIM(IF(COUNTIFS($C$22:$C$210,B14,$D$22:$D$210,"*Erros*",$O$22:$O$210,"<>Cancelada")>0,"Erros ","")&IF(COUNTIFS($C$22:$C$210,B14,$D$22:$D$210,"*Suporte*",$O$22:$O$210,"<>Cancelada")>0,"Suporte ","")&IF(COUNTIFS($C$22:$C$210,B14,$D$22:$D$210,"*Vistoria*",$O$22:$O$210,"<>Cancelada")>0,"Vistoria ","")&IF(COUNTIFS($C$22:$C$210,B14,$D$22:$D$210,"*Metas*",$O$22:$O$210,"<>Cancelada")>0,"Metas ","")&IF(COUNTIFS($C$22:$C$210,B14,$D$22:$D$210,"*Faltas*",$O$22:$O$210,"<>Cancelada")>0,"Faltas ","")&IF(COUNTIFS($C$22:$C$210,B14,$D$22:$D$210,"*Semanal c/*",$O$22:$O$210,"<>Cancelada")>0,"Acomp. ","")&IF(COUNTIFS($C$22:$C$210,B14,$D$22:$D$210,"*Reunião*",$O$22:$O$210,"<>Cancelada")>0,"Reunião ","")&IF(COUNTIFS($C$22:$C$210,B14,$D$22:$D$210,"*Férias*",$O$22:$O$210,"<>Cancelada")>0,"Férias ","")&IF(COUNTIFS($C$22:$C$210,B14,$D$22:$D$210,"*Mudança*",$O$22:$O$210,"<>Cancelada")>0,"M.Função ","")&IF(COUNTIFS($C$22:$C$210,B14,$D$22:$D$210,"*Treinamento*",$O$22:$O$210,"<>Cancelada")>0,"Trein. ",""))) | D15: =IF(D14="","",TRIM(IF(COUNTIFS($C$22:$C$210,D14,$D$22:$D$210,"*Erros*",$O$22:$O$210,"<>Cancelada")>0,"Erros ","")&IF(COUNTIFS($C$22:$C$210,D14,$D$22:$D$210,"*Suporte*",$O$22:$O$210,"<>Cancelada")>0,"Suporte ","")&IF(COUNTIFS($C$22:$C$210,D14,$D$22:$D$210,"*Vistoria*",$O$22:$O$210,"<>Cancelada")>0,"Vistoria ","")&IF(COUNTIFS($C$22:$C$210,D14,$D$22:$D$210,"*Metas*",$O$22:$O$210,"<>Cancelada")>0,"Metas ","")&IF(COUNTIFS($C$22:$C$210,D14,$D$22:$D$210,"*Faltas*",$O$22:$O$210,"<>Cancelada")>0,"Faltas ","")&IF(COUNTIFS($C$22:$C$210,D14,$D$22:$D$210,"*Semanal c/*",$O$22:$O$210,"<>Cancelada")>0,"Acomp. ","")&IF(COUNTIFS($C$22:$C$210,D14,$D$22:$D$210,"*Reunião*",$O$22:$O$210,"<>Cancelada")>0,"Reunião ","")&IF(COUNTIFS($C$22:$C$210,D14,$D$22:$D$210,"*Férias*",$O$22:$O$210,"<>Cancelada")>0,"Férias ","")&IF(COUNTIFS($C$22:$C$210,D14,$D$22:$D$210,"*Mudança*",$O$22:$O$210,"<>Cancelada")>0,"M.Função ","")&IF(COUNTIFS($C$22:$C$210,D14,$D$22:$D$210,"*Treinamento*",$O$22:$O$210,"<>Cancelada")>0,"Trein. ",""))) | F15: =IF(F14="","",TRIM(IF(COUNTIFS($C$22:$C$210,F14,$D$22:$D$210,"*Erros*",$O$22:$O$210,"<>Cancelada")>0,"Erros ","")&IF(COUNTIFS($C$22:$C$210,F14,$D$22:$D$210,"*Suporte*",$O$22:$O$210,"<>Cancelada")>0,"Suporte ","")&IF(COUNTIFS($C$22:$C$210,F14,$D$22:$D$210,"*Vistoria*",$O$22:$O$210,"<>Cancelada")>0,"Vistoria ","")&IF(COUNTIFS($C$22:$C$210,F14,$D$22:$D$210,"*Metas*",$O$22:$O$210,"<>Cancelada")>0,"Metas ","")&IF(COUNTIFS($C$22:$C$210,F14,$D$22:$D$210,"*Faltas*",$O$22:$O$210,"<>Cancelada")>0,"Faltas ","")&IF(COUNTIFS($C$22:$C$210,F14,$D$22:$D$210,"*Semanal c/*",$O$22:$O$210,"<>Cancelada")>0,"Acomp. ","")&IF(COUNTIFS($C$22:$C$210,F14,$D$22:$D$210,"*Reunião*",$O$22:$O$210,"<>Cancelada")>0,"Reunião ","")&IF(COUNTIFS($C$22:$C$210,F14,$D$22:$D$210,"*Férias*",$O$22:$O$210,"<>Cancelada")>0,"Férias ","")&IF(COUNTIFS($C$22:$C$210,F14,$D$22:$D$210,"*Mudança*",$O$22:$O$210,"<>Cancelada")>0,"M.Função ","")&IF(COUNTIFS($C$22:$C$210,F14,$D$22:$D$210,"*Treinamento*",$O$22:$O$210,"<>Cancelada")>0,"Trein. ",""))) | H15: =IF(H14="","",TRIM(IF(COUNTIFS($C$22:$C$210,H14,$D$22:$D$210,"*Erros*",$O$22:$O$210,"<>Cancelada")>0,"Erros ","")&IF(COUNTIFS($C$22:$C$210,H14,$D$22:$D$210,"*Suporte*",$O$22:$O$210,"<>Cancelada")>0,"Suporte ","")&IF(COUNTIFS($C$22:$C$210,H14,$D$22:$D$210,"*Vistoria*",$O$22:$O$210,"<>Cancelada")>0,"Vistoria ","")&IF(COUNTIFS($C$22:$C$210,H14,$D$22:$D$210,"*Metas*",$O$22:$O$210,"<>Cancelada")>0,"Metas ","")&IF(COUNTIFS($C$22:$C$210,H14,$D$22:$D$210,"*Faltas*",$O$22:$O$210,"<>Cancelada")>0,"Faltas ","")&IF(COUNTIFS($C$22:$C$210,H14,$D$22:$D$210,"*Semanal c/*",$O$22:$O$210,"<>Cancelada")>0,"Acomp. ","")&IF(COUNTIFS($C$22:$C$210,H14,$D$22:$D$210,"*Reunião*",$O$22:$O$210,"<>Cancelada")>0,"Reunião ","")&IF(COUNTIFS($C$22:$C$210,H14,$D$22:$D$210,"*Férias*",$O$22:$O$210,"<>Cancelada")>0,"Férias ","")&IF(COUNTIFS($C$22:$C$210,H14,$D$22:$D$210,"*Mudança*",$O$22:$O$210,"<>Cancelada")>0,"M.Função ","")&IF(COUNTIFS($C$22:$C$210,H14,$D$22:$D$210,"*Treinamento*",$O$22:$O$210,"<>Cancelada")>0,"Trein. ",""))) | J15: =IF(J14="","",TRIM(IF(COUNTIFS($C$22:$C$210,J14,$D$22:$D$210,"*Erros*",$O$22:$O$210,"<>Cancelada")>0,"Erros ","")&IF(COUNTIFS($C$22:$C$210,J14,$D$22:$D$210,"*Suporte*",$O$22:$O$210,"<>Cancelada")>0,"Suporte ","")&IF(COUNTIFS($C$22:$C$210,J14,$D$22:$D$210,"*Vistoria*",$O$22:$O$210,"<>Cancelada")>0,"Vistoria ","")&IF(COUNTIFS($C$22:$C$210,J14,$D$22:$D$210,"*Metas*",$O$22:$O$210,"<>Cancelada")>0,"Metas ","")&IF(COUNTIFS($C$22:$C$210,J14,$D$22:$D$210,"*Faltas*",$O$22:$O$210,"<>Cancelada")>0,"Faltas ","")&IF(COUNTIFS($C$22:$C$210,J14,$D$22:$D$210,"*Semanal c/*",$O$22:$O$210,"<>Cancelada")>0,"Acomp. ","")&IF(COUNTIFS($C$22:$C$210,J14,$D$22:$D$210,"*Reunião*",$O$22:$O$210,"<>Cancelada")>0,"Reunião ","")&IF(COUNTIFS($C$22:$C$210,J14,$D$22:$D$210,"*Férias*",$O$22:$O$210,"<>Cancelada")>0,"Férias ","")&IF(COUNTIFS($C$22:$C$210,J14,$D$22:$D$210,"*Mudança*",$O$22:$O$210,"<>Cancelada")>0,"M.Função ","")&IF(COUNTIFS($C$22:$C$210,J14,$D$22:$D$210,"*Treinamento*",$O$22:$O$210,"<>Cancelada")>0,"Trein. ",""))) | L15: =IF(L14="","",TRIM(IF(COUNTIFS($C$22:$C$210,L14,$D$22:$D$210,"*Erros*",$O$22:$O$210,"<>Cancelada")>0,"Erros ","")&IF(COUNTIFS($C$22:$C$210,L14,$D$22:$D$210,"*Suporte*",$O$22:$O$210,"<>Cancelada")>0,"Suporte ","")&IF(COUNTIFS($C$22:$C$210,L14,$D$22:$D$210,"*Vistoria*",$O$22:$O$210,"<>Cancelada")>0,"Vistoria ","")&IF(COUNTIFS($C$22:$C$210,L14,$D$22:$D$210,"*Metas*",$O$22:$O$210,"<>Cancelada")>0,"Metas ","")&IF(COUNTIFS($C$22:$C$210,L14,$D$22:$D$210,"*Faltas*",$O$22:$O$210,"<>Cancelada")>0,"Faltas ","")&IF(COUNTIFS($C$22:$C$210,L14,$D$22:$D$210,"*Semanal c/*",$O$22:$O$210,"<>Cancelada")>0,"Acomp. ","")&IF(COUNTIFS($C$22:$C$210,L14,$D$22:$D$210,"*Reunião*",$O$22:$O$210,"<>Cancelada")>0,"Reunião ","")&IF(COUNTIFS($C$22:$C$210,L14,$D$22:$D$210,"*Férias*",$O$22:$O$210,"<>Cancelada")>0,"Férias ","")&IF(COUNTIFS($C$22:$C$210,L14,$D$22:$D$210,"*Mudança*",$O$22:$O$210,"<>Cancelada")>0,"M.Função ","")&IF(COUNTIFS($C$22:$C$210,L14,$D$22:$D$210,"*Treinamento*",$O$22:$O$210,"<>Cancelada")>0,"Trein. ","")))
B18: Amarelo = hoje - Azul = dia com prazo - SEX = reunião com a gerência - Acomp. = Acompanhamento c/ Supervisores - M.Função = Mudança de Função - Trein. = Treinamento programado
A20: GESTÃO DE ATIVIDADES — coordenador: selecione a linha e use o menu GSL Bartofil > Anexar entrega (ou cole o link na coluna LINK DO ANEXO)
A21: ID | B21: SEMANA | C21: PRAZO | D21: ATIVIDADE | G21: TURNO | H21: COORDENADOR | J21: SETOR (vistoria) | L21: LINK DO ANEXO (ENTREGA) | N21: ENTREGUE EM | O21: VALIDAÇÃO | P21: MOTIVO REPROV. / CANCEL. | R21: STATUS | S21: fL | T21: fA | U21: fE
A22: JUL-S27-ERR-A | B22: S27 | C22: 46204 | D22: Levantamento de Erros Operacionais | G22: A | H22: =IF($G22="A",CONFIG!$B$5,IF($G22="B",CONFIG!$B$6,IF($G22="C",CONFIG!$B$7,IF($G22="Todos","Todos os turnos","")))) | J22: — | R22: =IF($C22="","",IF($O22="Cancelada","Cancelada",IF($O22="Reprovado","Reprovada",IF($O22="Aprovado","Aprovada",IF($L22<>"","Entregue",IF(TODAY()>$C22,"Atrasada","Pendente"))))))
A23: JUL-S27-ERR-B | B23: S27 | C23: 46204 | D23: Levantamento de Erros Operacionais | G23: B | H23: =IF($G23="A",CONFIG!$B$5,IF($G23="B",CONFIG!$B$6,IF($G23="C",CONFIG!$B$7,IF($G23="Todos","Todos os turnos","")))) | J23: — | R23: =IF($C23="","",IF($O23="Cancelada","Cancelada",IF($O23="Reprovado","Reprovada",IF($O23="Aprovado","Aprovada",IF($L23<>"","Entregue",IF(TODAY()>$C23,"Atrasada","Pendente"))))))
A24: JUL-S27-ERR-C | B24: S27 | C24: 46204 | D24: Levantamento de Erros Operacionais | G24: C | H24: =IF($G24="A",CONFIG!$B$5,IF($G24="B",CONFIG!$B$6,IF($G24="C",CONFIG!$B$7,IF($G24="Todos","Todos os turnos","")))) | J24: — | R24: =IF($C24="","",IF($O24="Cancelada","Cancelada",IF($O24="Reprovado","Reprovada",IF($O24="Aprovado","Aprovada",IF($L24<>"","Entregue",IF(TODAY()>$C24,"Atrasada","Pendente"))))))
A25: JUL-S27-SUP-A | B25: S27 | C25: 46204 | D25: Suporte de Supervisores | G25: A | H25: =IF($G25="A",CONFIG!$B$5,IF($G25="B",CONFIG!$B$6,IF($G25="C",CONFIG!$B$7,IF($G25="Todos","Todos os turnos","")))) | J25: — | R25: =IF($C25="","",IF($O25="Cancelada","Cancelada",IF($O25="Reprovado","Reprovada",IF($O25="Aprovado","Aprovada",IF($L25<>"","Entregue",IF(TODAY()>$C25,"Atrasada","Pendente"))))))
A26: JUL-S27-SUP-B | B26: S27 | C26: 46204 | D26: Suporte de Supervisores | G26: B | H26: =IF($G26="A",CONFIG!$B$5,IF($G26="B",CONFIG!$B$6,IF($G26="C",CONFIG!$B$7,IF($G26="Todos","Todos os turnos","")))) | J26: — | R26: =IF($C26="","",IF($O26="Cancelada","Cancelada",IF($O26="Reprovado","Reprovada",IF($O26="Aprovado","Aprovada",IF($L26<>"","Entregue",IF(TODAY()>$C26,"Atrasada","Pendente"))))))
A27: JUL-S27-SUP-C | B27: S27 | C27: 46204 | D27: Suporte de Supervisores | G27: C | H27: =IF($G27="A",CONFIG!$B$5,IF($G27="B",CONFIG!$B$6,IF($G27="C",CONFIG!$B$7,IF($G27="Todos","Todos os turnos","")))) | J27: — | R27: =IF($C27="","",IF($O27="Cancelada","Cancelada",IF($O27="Reprovado","Reprovada",IF($O27="Aprovado","Aprovada",IF($L27<>"","Entregue",IF(TODAY()>$C27,"Atrasada","Pendente"))))))
A28: JUL-S27-VIS-A | B28: S27 | C28: 46204 | D28: Acomp. Organizacional Setorial (Vistoria) | G28: A | H28: =IF($G28="A",CONFIG!$B$5,IF($G28="B",CONFIG!$B$6,IF($G28="C",CONFIG!$B$7,IF($G28="Todos","Todos os turnos","")))) | R28: =IF($C28="","",IF($O28="Cancelada","Cancelada",IF($O28="Reprovado","Reprovada",IF($O28="Aprovado","Aprovada",IF($L28<>"","Entregue",IF(TODAY()>$C28,"Atrasada","Pendente"))))))
A29: JUL-S27-VIS-B | B29: S27 | C29: 46204 | D29: Acomp. Organizacional Setorial (Vistoria) | G29: B | H29: =IF($G29="A",CONFIG!$B$5,IF($G29="B",CONFIG!$B$6,IF($G29="C",CONFIG!$B$7,IF($G29="Todos","Todos os turnos","")))) | R29: =IF($C29="","",IF($O29="Cancelada","Cancelada",IF($O29="Reprovado","Reprovada",IF($O29="Aprovado","Aprovada",IF($L29<>"","Entregue",IF(TODAY()>$C29,"Atrasada","Pendente"))))))
A30: JUL-S27-VIS-C | B30: S27 | C30: 46204 | D30: Acomp. Organizacional Setorial (Vistoria) | G30: C | H30: =IF($G30="A",CONFIG!$B$5,IF($G30="B",CONFIG!$B$6,IF($G30="C",CONFIG!$B$7,IF($G30="Todos","Todos os turnos","")))) | R30: =IF($C30="","",IF($O30="Cancelada","Cancelada",IF($O30="Reprovado","Reprovada",IF($O30="Aprovado","Aprovada",IF($L30<>"","Entregue",IF(TODAY()>$C30,"Atrasada","Pendente"))))))
A31: JUL-S27-MET-A | B31: S27 | C31: 46205 | D31: Metas | G31: A | H31: =IF($G31="A",CONFIG!$B$5,IF($G31="B",CONFIG!$B$6,IF($G31="C",CONFIG!$B$7,IF($G31="Todos","Todos os turnos","")))) | J31: — | R31: =IF($C31="","",IF($O31="Cancelada","Cancelada",IF($O31="Reprovado","Reprovada",IF($O31="Aprovado","Aprovada",IF($L31<>"","Entregue",IF(TODAY()>$C31,"Atrasada","Pendente"))))))
A32: JUL-S27-MET-B | B32: S27 | C32: 46205 | D32: Metas | G32: B | H32: =IF($G32="A",CONFIG!$B$5,IF($G32="B",CONFIG!$B$6,IF($G32="C",CONFIG!$B$7,IF($G32="Todos","Todos os turnos","")))) | J32: — | R32: =IF($C32="","",IF($O32="Cancelada","Cancelada",IF($O32="Reprovado","Reprovada",IF($O32="Aprovado","Aprovada",IF($L32<>"","Entregue",IF(TODAY()>$C32,"Atrasada","Pendente"))))))
A33: JUL-S27-MET-C | B33: S27 | C33: 46205 | D33: Metas | G33: C | H33: =IF($G33="A",CONFIG!$B$5,IF($G33="B",CONFIG!$B$6,IF($G33="C",CONFIG!$B$7,IF($G33="Todos","Todos os turnos","")))) | J33: — | R33: =IF($C33="","",IF($O33="Cancelada","Cancelada",IF($O33="Reprovado","Reprovada",IF($O33="Aprovado","Aprovada",IF($L33<>"","Entregue",IF(TODAY()>$C33,"Atrasada","Pendente"))))))
A34: JUL-S27-ACO-A | B34: S27 | C34: 46206 | D34: Acompanhamento Semanal c/ Supervisores | G34: A | H34: =IF($G34="A",CONFIG!$B$5,IF($G34="B",CONFIG!$B$6,IF($G34="C",CONFIG!$B$7,IF($G34="Todos","Todos os turnos","")))) | J34: — | R34: =IF($C34="","",IF($O34="Cancelada","Cancelada",IF($O34="Reprovado","Reprovada",IF($O34="Aprovado","Aprovada",IF($L34<>"","Entregue",IF(TODAY()>$C34,"Atrasada","Pendente"))))))
A35: JUL-S27-ACO-B | B35: S27 | C35: 46206 | D35: Acompanhamento Semanal c/ Supervisores | G35: B | H35: =IF($G35="A",CONFIG!$B$5,IF($G35="B",CONFIG!$B$6,IF($G35="C",CONFIG!$B$7,IF($G35="Todos","Todos os turnos","")))) | J35: — | R35: =IF($C35="","",IF($O35="Cancelada","Cancelada",IF($O35="Reprovado","Reprovada",IF($O35="Aprovado","Aprovada",IF($L35<>"","Entregue",IF(TODAY()>$C35,"Atrasada","Pendente"))))))
A36: JUL-S27-ACO-C | B36: S27 | C36: 46206 | D36: Acompanhamento Semanal c/ Supervisores | G36: C | H36: =IF($G36="A",CONFIG!$B$5,IF($G36="B",CONFIG!$B$6,IF($G36="C",CONFIG!$B$7,IF($G36="Todos","Todos os turnos","")))) | J36: — | R36: =IF($C36="","",IF($O36="Cancelada","Cancelada",IF($O36="Reprovado","Reprovada",IF($O36="Aprovado","Aprovada",IF($L36<>"","Entregue",IF(TODAY()>$C36,"Atrasada","Pendente"))))))
A37: JUL-S27-FAL-A | B37: S27 | C37: 46206 | D37: Faltas e Atestados | G37: A | H37: =IF($G37="A",CONFIG!$B$5,IF($G37="B",CONFIG!$B$6,IF($G37="C",CONFIG!$B$7,IF($G37="Todos","Todos os turnos","")))) | J37: — | R37: =IF($C37="","",IF($O37="Cancelada","Cancelada",IF($O37="Reprovado","Reprovada",IF($O37="Aprovado","Aprovada",IF($L37<>"","Entregue",IF(TODAY()>$C37,"Atrasada","Pendente"))))))
A38: JUL-S27-FAL-B | B38: S27 | C38: 46206 | D38: Faltas e Atestados | G38: B | H38: =IF($G38="A",CONFIG!$B$5,IF($G38="B",CONFIG!$B$6,IF($G38="C",CONFIG!$B$7,IF($G38="Todos","Todos os turnos","")))) | J38: — | R38: =IF($C38="","",IF($O38="Cancelada","Cancelada",IF($O38="Reprovado","Reprovada",IF($O38="Aprovado","Aprovada",IF($L38<>"","Entregue",IF(TODAY()>$C38,"Atrasada","Pendente"))))))
A39: JUL-S27-FAL-C | B39: S27 | C39: 46206 | D39: Faltas e Atestados | G39: C | H39: =IF($G39="A",CONFIG!$B$5,IF($G39="B",CONFIG!$B$6,IF($G39="C",CONFIG!$B$7,IF($G39="Todos","Todos os turnos","")))) | J39: — | R39: =IF($C39="","",IF($O39="Cancelada","Cancelada",IF($O39="Reprovado","Reprovada",IF($O39="Aprovado","Aprovada",IF($L39<>"","Entregue",IF(TODAY()>$C39,"Atrasada","Pendente"))))))
A40: JUL-S27-REU-T | B40: S27 | C40: 46206 | D40: Reunião Semanal com a Gerência | G40: Todos | H40: =IF($G40="A",CONFIG!$B$5,IF($G40="B",CONFIG!$B$6,IF($G40="C",CONFIG!$B$7,IF($G40="Todos","Todos os turnos","")))) | J40: — | R40: =IF($C40="","",IF($O40="Cancelada","Cancelada",IF($O40="Reprovado","Reprovada",IF($O40="Aprovado","Aprovada",IF($L40<>"","Entregue",IF(TODAY()>$C40,"Atrasada","Pendente"))))))
A41: JUL-S28-FER-A | B41: S28 | C41: 46209 | D41: Programação de Férias (mensal) | G41: A | H41: =IF($G41="A",CONFIG!$B$5,IF($G41="B",CONFIG!$B$6,IF($G41="C",CONFIG!$B$7,IF($G41="Todos","Todos os turnos","")))) | J41: — | R41: =IF($C41="","",IF($O41="Cancelada","Cancelada",IF($O41="Reprovado","Reprovada",IF($O41="Aprovado","Aprovada",IF($L41<>"","Entregue",IF(TODAY()>$C41,"Atrasada","Pendente"))))))
A42: JUL-S28-FER-B | B42: S28 | C42: 46209 | D42: Programação de Férias (mensal) | G42: B | H42: =IF($G42="A",CONFIG!$B$5,IF($G42="B",CONFIG!$B$6,IF($G42="C",CONFIG!$B$7,IF($G42="Todos","Todos os turnos","")))) | J42: — | R42: =IF($C42="","",IF($O42="Cancelada","Cancelada",IF($O42="Reprovado","Reprovada",IF($O42="Aprovado","Aprovada",IF($L42<>"","Entregue",IF(TODAY()>$C42,"Atrasada","Pendente"))))))
... A49: JUL-S28-SUP-C | B49: S28 | C49: 46210 | D49: Suporte de Supervisores | G49: C | H49: =IF($G49="A",CONFIG!$B$5,IF($G49="B",CONFIG!$B$6,IF($G49="C",CONFIG!$B$7,IF($G49="Todos","Todos os turnos","")))) | J49: — | R49: =IF($C49="","",IF($O49="Cancelada","Cancelada",IF($O49="Reprovado","Reprovada",IF($O49="Aprovado","Aprovada",IF($L49<>"","Entregue",IF(TODAY()>$C49,"Atrasada","Pendente"))))))
A50: JUL-S28-VIS-A | B50: S28 | C50: 46211 | D50: Acomp. Organizacional Setorial (Vistoria) | G50: A | H50: =IF($G50="A",CONFIG!$B$5,IF($G50="B",CONFIG!$B$6,IF($G50="C",CONFIG!$B$7,IF($G50="Todos","Todos os turnos","")))) | R50: =IF($C50="","",IF($O50="Cancelada","Cancelada",IF($O50="Reprovado","Reprovada",IF($O50="Aprovado","Aprovada",IF($L50<>"","Entregue",IF(TODAY()>$C50,"Atrasada","Pendente"))))))
A51: JUL-S28-VIS-B | B51: S28 | C51: 46211 | D51: Acomp. Organizacional Setorial (Vistoria) | G51: B | H51: =IF($G51="A",CONFIG!$B$5,IF($G51="B",CONFIG!$B$6,IF($G51="C",CONFIG!$B$7,IF($G51="Todos","Todos os turnos","")))) | R51: =IF($C51="","",IF($O51="Cancelada","Cancelada",IF($O51="Reprovado","Reprovada",IF($O51="Aprovado","Aprovada",IF($L51<>"","Entregue",IF(TODAY()>$C51,"Atrasada","Pendente"))))))
...

Sheet AGO 2026
A1: 08 · AGOSTO 2026 | O1: GSL BARTOFIL
A3: =IF((COUNTIF($R$22:$R$210,"Aprovada")+COUNTIF($R$22:$R$210,"Entregue")+COUNTIF($R$22:$R$210,"Pendente")+COUNTIF($R$22:$R$210,"Atrasada")+COUNTIF($R$22:$R$210,"Reprovada"))=0,"",IF(COUNTIF($R$22:$R$210,"Aprovada")=(COUNTIF($R$22:$R$210,"Aprovada")+COUNTIF($R$22:$R$210,"Entregue")+COUNTIF($R$22:$R$210,"Pendente")+COUNTIF($R$22:$R$210,"Atrasada")+COUNTIF($R$22:$R$210,"Reprovada")),"MÊS CONCLUÍDO — todas as atividades aprovadas","EM ANDAMENTO — "&COUNTIF($R$22:$R$210,"Aprovada")&" de "&(COUNTIF($R$22:$R$210,"Aprovada")+COUNTIF($R$22:$R$210,"Entregue")+COUNTIF($R$22:$R$210,"Pendente")+COUNTIF($R$22:$R$210,"Atrasada")+COUNTIF($R$22:$R$210,"Reprovada"))&" atividades aprovadas"))
B5: DOM | D5: SEG | F5: TER | H5: QUA | J5: QUI | L5: SEX | N5: SÁB
N6: 46235
N7: =IF(N6="","",TRIM(IF(COUNTIFS($C$22:$C$210,N6,$D$22:$D$210,"*Erros*",$O$22:$O$210,"<>Cancelada")>0,"Erros ","")&IF(COUNTIFS($C$22:$C$210,N6,$D$22:$D$210,"*Suporte*",$O$22:$O$210,"<>Cancelada")>0,"Suporte ","")&IF(COUNTIFS($C$22:$C$210,N6,$D$22:$D$210,"*Vistoria*",$O$22:$O$210,"<>Cancelada")>0,"Vistoria ","")&IF(COUNTIFS($C$22:$C$210,N6,$D$22:$D$210,"*Metas*",$O$22:$O$210,"<>Cancelada")>0,"Metas ","")&IF(COUNTIFS($C$22:$C$210,N6,$D$22:$D$210,"*Faltas*",$O$22:$O$210,"<>Cancelada")>0,"Faltas ","")&IF(COUNTIFS($C$22:$C$210,N6,$D$22:$D$210,"*Semanal c/*",$O$22:$O$210,"<>Cancelada")>0,"Acomp. ","")&IF(COUNTIFS($C$22:$C$210,N6,$D$22:$D$210,"*Reunião*",$O$22:$O$210,"<>Cancelada")>0,"Reunião ","")&IF(COUNTIFS($C$22:$C$210,N6,$D$22:$D$210,"*Férias*",$O$22:$O$210,"<>Cancelada")>0,"Férias ","")&IF(COUNTIFS($C$22:$C$210,N6,$D$22:$D$210,"*Mudança*",$O$22:$O$210,"<>Cancelada")>0,"M.Função ","")&IF(COUNTIFS($C$22:$C$210,N6,$D$22:$D$210,"*Treinamento*",$O$22:$O$210,"<>Cancelada")>0,"Trein. ","")))
B8: 46236 | D8: 46237 | F8: 46238 | H8: 46239 | J8: 46240 | L8: 46241 | N8: 46242
