Workbook

Sheet INÍCIO
A1: GSL BARTOFIL — SISTEMA DE GESTÃO OPERACIONAL · CD FEIRA DE SANTANA
A3: Turnos A (manhã) · B (tarde) · C (noite) — a semana orbita a VISTORIA de quarta e a REUNIÃO de sexta. Meses novos são gerados automaticamente pelo script.
A5: A SEMANA — 3 compromissos, tudo apontando para a reunião
A6: QUA | B6: Vistoria Setorial | C6: Checklist impresso no setor definido pelo gerente; anexar escaneado.
A7: QUI | B7: Relatório Semanal Consolidado | C7: UM único documento por turno: erros + metas + faltas/atestados + supervisores. O conteúdo vem das planilhas dos setores; aqui só se controla a entrega e a validação.
A8: SEX | B8: Reunião Semanal com a Gerência | C8: O marco da semana. O gerente chega com a pauta pronta (aba GERÊNCIA + briefing por e-mail) e valida as entregas.
B9: Mensais: Programação de Férias (1ª segunda) · Mudança de Função (última sexta) · Treinamentos (quando o gerente marcar).
A11: MODELOS PARA DOWNLOAD — administrador: cole ao lado o link de cada arquivo no Drive
A12: 1. | B12: Relatório Semanal Consolidado (QUI) — Modelo-Relatorio-Semanal.docx | C12: (cole aqui o link do arquivo no Drive)
A13: 2. | B13: Checklist de Vistoria (QUA) — Checklist-Vistoria.docx | C13: (cole aqui o link do arquivo no Drive)
B14: Compartilhe como 'qualquer pessoa com o link pode ver'. Os links entram automaticamente nos e-mails.
A16: O SISTEMA — acompanhamento, insights e meses infinitos
B17: Escopo do GSL | C17: Esta planilha controla SÓ atividades: o que foi programado, quem entregou, quando e se o gerente aprovou. Nenhum dado individual de colaborador é digitado ou guardado aqui.
B18: Aba CENTRAL | C18: Andamento geral: total programado, aprovadas, atrasadas e % de conclusão — mês a mês até DEZ/2027 e acumulado por turno (A, B e C).
B19: Aba INSIGHTS | C19: O script analisa o próprio calendário e escreve diagnósticos em português: atrasos recorrentes, reprovações, turno fora da curva e concentração por dia da semana. Roda toda 5ª e no fechamento do mês.
B20: Planilha GSL-DADOS | C20: Planilha SEPARADA que recebe RH (faltas, atestados, saídas), erros e metas dos setores e alimenta o BI. Coordenadores não têm acesso a ela — no GSL eles só veem as próprias atividades.
B21: Meses automáticos | C21: Todo dia 20 o script gera a aba do mês seguinte sozinho (ou use o menu Gerar aba do próximo mês). CENTRAL já espera os meses até DEZ/2027.
B22: E-mails automáticos | C22: Digesto matinal único por coordenador (atrasadas, hoje, AMANHÃ, próximos), briefing do gerente na véspera e no dia da reunião, e avisos em tempo real de entregas, validações e prazos.
A25: INSTALAÇÃO (5 min) — APÓS IMPORTAR NO GOOGLE DRIVE
A26: 1. | B26: OBRIGATÓRIO: Arquivo → Salvar como Planilhas Google (em modo .xlsx o script NÃO roda).
A27: 2. | B27: Extensões → Apps Script → cole o Code.gs entregue junto e salve.
A28: 3. | B28: Preencha a aba CONFIG (nomes e e-mails da equipe).
A29: 4. | B29: No Apps Script, execute instalarGatilhos uma vez e autorize com a conta do gerente ou do administrador.
A30: 5. | B30: Recarregue a página: o menu GSL Bartofil aparece na barra. Cada coordenador autoriza no 1º uso.
A31: 6. | B31: Suba os 2 modelos Word na subpasta Modelos da pasta do Drive e cole os links acima.
A32: 7. | B32: Recomendado: proteja as colunas do gerente (Dados → Proteger intervalos): PRAZO C, SETOR J, VALIDAÇÃO Q, MOTIVO R.
A33: 8. | B33: NÃO exclua nem renomeie a aba oculta MODELO_MES — é dela que o script cria os meses novos.
B35: Identidade visual: paleta oficial Bartofil — azul #111785, verde #01973A e amarelo #FFEE03.

Sheet INSIGHTS
A1: INSIGHTS — O QUE OS DADOS ESTÃO DIZENDO
A3: Diagnósticos gerados automaticamente pelo script a partir das abas mensais deste calendário: atrasos recorrentes, reprovações, turno fora da curva e concentração por dia da semana. Atualiza sozinho toda 5ª-feira e no fechamento do mês — ou na hora: GSL Bartofil > Gerar insights agora. Análises de faltas, erros e metas ficam no BI da planilha GSL-DADOS. 🔴 crítico · 🟡 atenção · 🟢 positivo.
A5: GERADO EM | B5: NÍVEL | C5: INSIGHT | D5: RECOMENDAÇÃO
C6: (ainda sem análise — use o menu GSL Bartofil > Gerar insights agora)

Sheet CENTRAL
A1: CENTRAL — ANDAMENTO GERAL
A3: TOTAL PROGRAMADO | C3: APROVADAS | E3: ATRASADAS AGORA | G3: % CONCLUÍDO | I3: =TEXT(TODAY(),"dd/mm/yyyy")&" — visão geral" -> 05/08/2026 — visão geral
A4: =SUM(B8:B25) -> 212 | C4: =SUM(C8:C25) -> 0 | E4: =SUM(F8:F25) -> 42 | G4: =IF(SUM(B8:B25)=0,0,SUM(C8:C25)/SUM(B8:B25)) -> 0
A6: ANDAMENTO MÊS A MÊS — meses futuros aparecem sozinhos quando o script gera a aba
A7: MÊS | B7: TOTAL | C7: APROV. | D7: AGUARD. VALID. | E7: PEND. | F7: ATRAS. | G7: REPROV. | H7: % CONCL. | I7: PROGRESSO | J7: SITUAÇÃO
A8: =CHOOSE(MONTH($L8),"JAN","FEV","MAR","ABR","MAI","JUN","JUL","AGO","SET","OUT","NOV","DEZ")&" "&YEAR($L8) -> JUL 2026 | B8: =IFERROR(COUNTIF(INDIRECT("'"&$A8&"'!$S$22:$S$150"),"Aprovada"),0)+IFERROR(COUNTIF(INDIRECT("'"&$A8&"'!$S$22:$S$150"),"Entregue"),0)+IFERROR(COUNTIF(INDIRECT("'"&$A8&"'!$S$22:$S$150"),"Pendente"),0)+IFERROR(COUNTIF(INDIRECT("'"&$A8&"'!$S$22:$S$150"),"Atrasada"),0)+IFERROR(COUNTIF(INDIRECT("'"&$A8&"'!$S$22:$S$150"),"Reprovada"),0) -> 39 | C8: =IFERROR(COUNTIF(INDIRECT("'"&$A8&"'!$S$22:$S$150"),"Aprovada"),0) -> 0 | D8: =IFERROR(COUNTIF(INDIRECT("'"&$A8&"'!$S$22:$S$150"),"Entregue"),0) -> 0 | E8: =IFERROR(COUNTIF(INDIRECT("'"&$A8&"'!$S$22:$S$150"),"Pendente"),0) -> 0 | F8: =IFERROR(COUNTIF(INDIRECT("'"&$A8&"'!$S$22:$S$150"),"Atrasada"),0) -> 39 | G8: =IFERROR(COUNTIF(INDIRECT("'"&$A8&"'!$S$22:$S$150"),"Reprovada"),0) -> 0 | H8: =IF($B8=0,0,$C8/$B8) -> 0 | I8: =IF($B8=0,"",REPT("█",ROUND($H8*15,0))&REPT("░",15-ROUND($H8*15,0))) -> ░░░░░░░░░░░░░░░ | J8: =IF($B8=0,"—",IF($C8=$B8,"Concluído",IF($F8>0,"Com atrasos","Em andamento"))) -> Com atrasos | L8: =EDATE(DATE(2026,7,1),0) -> 46204
A9: =CHOOSE(MONTH($L9),"JAN","FEV","MAR","ABR","MAI","JUN","JUL","AGO","SET","OUT","NOV","DEZ")&" "&YEAR($L9) -> AGO 2026 | B9: =IFERROR(COUNTIF(INDIRECT("'"&$A9&"'!$S$22:$S$150"),"Aprovada"),0)+IFERROR(COUNTIF(INDIRECT("'"&$A9&"'!$S$22:$S$150"),"Entregue"),0)+IFERROR(COUNTIF(INDIRECT("'"&$A9&"'!$S$22:$S$150"),"Pendente"),0)+IFERROR(COUNTIF(INDIRECT("'"&$A9&"'!$S$22:$S$150"),"Atrasada"),0)+IFERROR(COUNTIF(INDIRECT("'"&$A9&"'!$S$22:$S$150"),"Reprovada"),0) -> 32 | C9: =IFERROR(COUNTIF(INDIRECT("'"&$A9&"'!$S$22:$S$150"),"Aprovada"),0) -> 0 | D9: =IFERROR(COUNTIF(INDIRECT("'"&$A9&"'!$S$22:$S$150"),"Entregue"),0) -> 0 | E9: =IFERROR(COUNTIF(INDIRECT("'"&$A9&"'!$S$22:$S$150"),"Pendente"),0) -> 29 | F9: =IFERROR(COUNTIF(INDIRECT("'"&$A9&"'!$S$22:$S$150"),"Atrasada"),0) -> 3 | G9: =IFERROR(COUNTIF(INDIRECT("'"&$A9&"'!$S$22:$S$150"),"Reprovada"),0) -> 0 | H9: =IF($B9=0,0,$C9/$B9) -> 0 | I9: =IF($B9=0,"",REPT("█",ROUND($H9*15,0))&REPT("░",15-ROUND($H9*15,0))) -> ░░░░░░░░░░░░░░░ | J9: =IF($B9=0,"—",IF($C9=$B9,"Concluído",IF($F9>0,"Com atrasos","Em andamento"))) -> Com atrasos | L9: =EDATE(DATE(2026,7,1),1) -> 46235
A10: =CHOOSE(MONTH($L10),"JAN","FEV","MAR","ABR","MAI","JUN","JUL","AGO","SET","OUT","NOV","DEZ")&" "&YEAR($L10) -> SET 2026 | B10: =IFERROR(COUNTIF(INDIRECT("'"&$A10&"'!$S$22:$S$150"),"Aprovada"),0)+IFERROR(COUNTIF(INDIRECT("'"&$A10&"'!$S$22:$S$150"),"Entregue"),0)+IFERROR(COUNTIF(INDIRECT("'"&$A10&"'!$S$22:$S$150"),"Pendente"),0)+IFERROR(COUNTIF(INDIRECT("'"&$A10&"'!$S$22:$S$150"),"Atrasada"),0)+IFERROR(COUNTIF(INDIRECT("'"&$A10&"'!$S$22:$S$150"),"Reprovada"),0) -> 35 | C10: =IFERROR(COUNTIF(INDIRECT("'"&$A10&"'!$S$22:$S$150"),"Aprovada"),0) -> 0 | D10: =IFERROR(COUNTIF(INDIRECT("'"&$A10&"'!$S$22:$S$150"),"Entregue"),0) -> 0 | E10: =IFERROR(COUNTIF(INDIRECT("'"&$A10&"'!$S$22:$S$150"),"Pendente"),0) -> 35 | F10: =IFERROR(COUNTIF(INDIRECT("'"&$A10&"'!$S$22:$S$150"),"Atrasada"),0) -> 0 | G10: =IFERROR(COUNTIF(INDIRECT("'"&$A10&"'!$S$22:$S$150"),"Reprovada"),0) -> 0 | H10: =IF($B10=0,0,$C10/$B10) -> 0 | I10: =IF($B10=0,"",REPT("█",ROUND($H10*15,0))&REPT("░",15-ROUND($H10*15,0))) -> ░░░░░░░░░░░░░░░ | J10: =IF($B10=0,"—",IF($C10=$B10,"Concluído",IF($F10>0,"Com atrasos","Em andamento"))) -> Em andamento | L10: =EDATE(DATE(2026,7,1),2) -> 46266
A11: =CHOOSE(MONTH($L11),"JAN","FEV","MAR","ABR","MAI","JUN","JUL","AGO","SET","OUT","NOV","DEZ")&" "&YEAR($L11) -> OUT 2026 | B11: =IFERROR(COUNTIF(INDIRECT("'"&$A11&"'!$S$22:$S$150"),"Aprovada"),0)+IFERROR(COUNTIF(INDIRECT("'"&$A11&"'!$S$22:$S$150"),"Entregue"),0)+IFERROR(COUNTIF(INDIRECT("'"&$A11&"'!$S$22:$S$150"),"Pendente"),0)+IFERROR(COUNTIF(INDIRECT("'"&$A11&"'!$S$22:$S$150"),"Atrasada"),0)+IFERROR(COUNTIF(INDIRECT("'"&$A11&"'!$S$22:$S$150"),"Reprovada"),0) -> 36 | C11: =IFERROR(COUNTIF(INDIRECT("'"&$A11&"'!$S$22:$S$150"),"Aprovada"),0) -> 0 | D11: =IFERROR(COUNTIF(INDIRECT("'"&$A11&"'!$S$22:$S$150"),"Entregue"),0) -> 0 | E11: =IFERROR(COUNTIF(INDIRECT("'"&$A11&"'!$S$22:$S$150"),"Pendente"),0) -> 36 | F11: =IFERROR(COUNTIF(INDIRECT("'"&$A11&"'!$S$22:$S$150"),"Atrasada"),0) -> 0 | G11: =IFERROR(COUNTIF(INDIRECT("'"&$A11&"'!$S$22:$S$150"),"Reprovada"),0) -> 0 | H11: =IF($B11=0,0,$C11/$B11) -> 0 | I11: =IF($B11=0,"",REPT("█",ROUND($H11*15,0))&REPT("░",15-ROUND($H11*15,0))) -> ░░░░░░░░░░░░░░░ | J11: =IF($B11=0,"—",IF($C11=$B11,"Concluído",IF($F11>0,"Com atrasos","Em andamento"))) -> Em andamento | L11: =EDATE(DATE(2026,7,1),3) -> 46296
A12: =CHOOSE(MONTH($L12),"JAN","FEV","MAR","ABR","MAI","JUN","JUL","AGO","SET","OUT","NOV","DEZ")&" "&YEAR($L12) -> NOV 2026 | B12: =IFERROR(COUNTIF(INDIRECT("'"&$A12&"'!$S$22:$S$150"),"Aprovada"),0)+IFERROR(COUNTIF(INDIRECT("'"&$A12&"'!$S$22:$S$150"),"Entregue"),0)+IFERROR(COUNTIF(INDIRECT("'"&$A12&"'!$S$22:$S$150"),"Pendente"),0)+IFERROR(COUNTIF(INDIRECT("'"&$A12&"'!$S$22:$S$150"),"Atrasada"),0)+IFERROR(COUNTIF(INDIRECT("'"&$A12&"'!$S$22:$S$150"),"Reprovada"),0) -> 32 | C12: =IFERROR(COUNTIF(INDIRECT("'"&$A12&"'!$S$22:$S$150"),"Aprovada"),0) -> 0 | D12: =IFERROR(COUNTIF(INDIRECT("'"&$A12&"'!$S$22:$S$150"),"Entregue"),0) -> 0 | E12: =IFERROR(COUNTIF(INDIRECT("'"&$A12&"'!$S$22:$S$150"),"Pendente"),0) -> 32 | F12: =IFERROR(COUNTIF(INDIRECT("'"&$A12&"'!$S$22:$S$150"),"Atrasada"),0) -> 0 | G12: =IFERROR(COUNTIF(INDIRECT("'"&$A12&"'!$S$22:$S$150"),"Reprovada"),0) -> 0 | H12: =IF($B12=0,0,$C12/$B12) -> 0 | I12: =IF($B12=0,"",REPT("█",ROUND($H12*15,0))&REPT("░",15-ROUND($H12*15,0))) -> ░░░░░░░░░░░░░░░ | J12: =IF($B12=0,"—",IF($C12=$B12,"Concluído",IF($F12>0,"Com atrasos","Em andamento"))) -> Em andamento | L12: =EDATE(DATE(2026,7,1),4) -> 46327
A13: =CHOOSE(MONTH($L13),"JAN","FEV","MAR","ABR","MAI","JUN","JUL","AGO","SET","OUT","NOV","DEZ")&" "&YEAR($L13) -> DEZ 2026 | B13: =IFERROR(COUNTIF(INDIRECT("'"&$A13&"'!$S$22:$S$150"),"Aprovada"),0)+IFERROR(COUNTIF(INDIRECT("'"&$A13&"'!$S$22:$S$150"),"Entregue"),0)+IFERROR(COUNTIF(INDIRECT("'"&$A13&"'!$S$22:$S$150"),"Pendente"),0)+IFERROR(COUNTIF(INDIRECT("'"&$A13&"'!$S$22:$S$150"),"Atrasada"),0)+IFERROR(COUNTIF(INDIRECT("'"&$A13&"'!$S$22:$S$150"),"Reprovada"),0) -> 38 | C13: =IFERROR(COUNTIF(INDIRECT("'"&$A13&"'!$S$22:$S$150"),"Aprovada"),0) -> 0 | D13: =IFERROR(COUNTIF(INDIRECT("'"&$A13&"'!$S$22:$S$150"),"Entregue"),0) -> 0 | E13: =IFERROR(COUNTIF(INDIRECT("'"&$A13&"'!$S$22:$S$150"),"Pendente"),0) -> 38 | F13: =IFERROR(COUNTIF(INDIRECT("'"&$A13&"'!$S$22:$S$150"),"Atrasada"),0) -> 0 | G13: =IFERROR(COUNTIF(INDIRECT("'"&$A13&"'!$S$22:$S$150"),"Reprovada"),0) -> 0 | H13: =IF($B13=0,0,$C13/$B13) -> 0 | I13: =IF($B13=0,"",REPT("█",ROUND($H13*15,0))&REPT("░",15-ROUND($H13*15,0))) -> ░░░░░░░░░░░░░░░ | J13: =IF($B13=0,"—",IF($C13=$B13,"Concluído",IF($F13>0,"Com atrasos","Em andamento"))) -> Em andamento | L13: =EDATE(DATE(2026,7,1),5) -> 46357
A14: =CHOOSE(MONTH($L14),"JAN","FEV","MAR","ABR","MAI","JUN","JUL","AGO","SET","OUT","NOV","DEZ")&" "&YEAR($L14) -> JAN 2027 | B14: =IFERROR(COUNTIF(INDIRECT("'"&$A14&"'!$S$22:$S$150"),"Aprovada"),0)+IFERROR(COUNTIF(INDIRECT("'"&$A14&"'!$S$22:$S$150"),"Entregue"),0)+IFERROR(COUNTIF(INDIRECT("'"&$A14&"'!$S$22:$S$150"),"Pendente"),0)+IFERROR(COUNTIF(INDIRECT("'"&$A14&"'!$S$22:$S$150"),"Atrasada"),0)+IFERROR(COUNTIF(INDIRECT("'"&$A14&"'!$S$22:$S$150"),"Reprovada"),0) -> 0 | C14: =IFERROR(COUNTIF(INDIRECT("'"&$A14&"'!$S$22:$S$150"),"Aprovada"),0) -> 0 | D14: =IFERROR(COUNTIF(INDIRECT("'"&$A14&"'!$S$22:$S$150"),"Entregue"),0) -> 0 | E14: =IFERROR(COUNTIF(INDIRECT("'"&$A14&"'!$S$22:$S$150"),"Pendente"),0) -> 0 | F14: =IFERROR(COUNTIF(INDIRECT("'"&$A14&"'!$S$22:$S$150"),"Atrasada"),0) -> 0 | G14: =IFERROR(COUNTIF(INDIRECT("'"&$A14&"'!$S$22:$S$150"),"Reprovada"),0) -> 0 | H14: =IF($B14=0,0,$C14/$B14) -> 0 | I14: =IF($B14=0,"",REPT("█",ROUND($H14*15,0))&REPT("░",15-ROUND($H14*15,0))) | J14: =IF($B14=0,"—",IF($C14=$B14,"Concluído",IF($F14>0,"Com atrasos","Em andamento"))) -> — | L14: =EDATE(DATE(2026,7,1),6) -> 46388
A15: =CHOOSE(MONTH($L15),"JAN","FEV","MAR","ABR","MAI","JUN","JUL","AGO","SET","OUT","NOV","DEZ")&" "&YEAR($L15) -> FEV 2027 | B15: =IFERROR(COUNTIF(INDIRECT("'"&$A15&"'!$S$22:$S$150"),"Aprovada"),0)+IFERROR(COUNTIF(INDIRECT("'"&$A15&"'!$S$22:$S$150"),"Entregue"),0)+IFERROR(COUNTIF(INDIRECT("'"&$A15&"'!$S$22:$S$150"),"Pendente"),0)+IFERROR(COUNTIF(INDIRECT("'"&$A15&"'!$S$22:$S$150"),"Atrasada"),0)+IFERROR(COUNTIF(INDIRECT("'"&$A15&"'!$S$22:$S$150"),"Reprovada"),0) -> 0 | C15: =IFERROR(COUNTIF(INDIRECT("'"&$A15&"'!$S$22:$S$150"),"Aprovada"),0) -> 0 | D15: =IFERROR(COUNTIF(INDIRECT("'"&$A15&"'!$S$22:$S$150"),"Entregue"),0) -> 0 | E15: =IFERROR(COUNTIF(INDIRECT("'"&$A15&"'!$S$22:$S$150"),"Pendente"),0) -> 0 | F15: =IFERROR(COUNTIF(INDIRECT("'"&$A15&"'!$S$22:$S$150"),"Atrasada"),0) -> 0 | G15: =IFERROR(COUNTIF(INDIRECT("'"&$A15&"'!$S$22:$S$150"),"Reprovada"),0) -> 0 | H15: =IF($B15=0,0,$C15/$B15) -> 0 | I15: =IF($B15=0,"",REPT("█",ROUND($H15*15,0))&REPT("░",15-ROUND($H15*15,0))) | J15: =IF($B15=0,"—",IF($C15=$B15,"Concluído",IF($F15>0,"Com atrasos","Em andamento"))) -> — | L15: =EDATE(DATE(2026,7,1),7) -> 46419
A16: =CHOOSE(MONTH($L16),"JAN","FEV","MAR","ABR","MAI","JUN","JUL","AGO","SET","OUT","NOV","DEZ")&" "&YEAR($L16) -> MAR 2027 | B16: =IFERROR(COUNTIF(INDIRECT("'"&$A16&"'!$S$22:$S$150"),"Aprovada"),0)+IFERROR(COUNTIF(INDIRECT("'"&$A16&"'!$S$22:$S$150"),"Entregue"),0)+IFERROR(COUNTIF(INDIRECT("'"&$A16&"'!$S$22:$S$150"),"Pendente"),0)+IFERROR(COUNTIF(INDIRECT("'"&$A16&"'!$S$22:$S$150"),"Atrasada"),0)+IFERROR(COUNTIF(INDIRECT("'"&$A16&"'!$S$22:$S$150"),"Reprovada"),0) -> 0 | C16: =IFERROR(COUNTIF(INDIRECT("'"&$A16&"'!$S$22:$S$150"),"Aprovada"),0) -> 0 | D16: =IFERROR(COUNTIF(INDIRECT("'"&$A16&"'!$S$22:$S$150"),"Entregue"),0) -> 0 | E16: =IFERROR(COUNTIF(INDIRECT("'"&$A16&"'!$S$22:$S$150"),"Pendente"),0) -> 0 | F16: =IFERROR(COUNTIF(INDIRECT("'"&$A16&"'!$S$22:$S$150"),"Atrasada"),0) -> 0 | G16: =IFERROR(COUNTIF(INDIRECT("'"&$A16&"'!$S$22:$S$150"),"Reprovada"),0) -> 0 | H16: =IF($B16=0,0,$C16/$B16) -> 0 | I16: =IF($B16=0,"",REPT("█",ROUND($H16*15,0))&REPT("░",15-ROUND($H16*15,0))) | J16: =IF($B16=0,"—",IF($C16=$B16,"Concluído",IF($F16>0,"Com atrasos","Em andamento"))) -> — | L16: =EDATE(DATE(2026,7,1),8) -> 46447
A17: =CHOOSE(MONTH($L17),"JAN","FEV","MAR","ABR","MAI","JUN","JUL","AGO","SET","OUT","NOV","DEZ")&" "&YEAR($L17) -> ABR 2027 | B17: =IFERROR(COUNTIF(INDIRECT("'"&$A17&"'!$S$22:$S$150"),"Aprovada"),0)+IFERROR(COUNTIF(INDIRECT("'"&$A17&"'!$S$22:$S$150"),"Entregue"),0)+IFERROR(COUNTIF(INDIRECT("'"&$A17&"'!$S$22:$S$150"),"Pendente"),0)+IFERROR(COUNTIF(INDIRECT("'"&$A17&"'!$S$22:$S$150"),"Atrasada"),0)+IFERROR(COUNTIF(INDIRECT("'"&$A17&"'!$S$22:$S$150"),"Reprovada"),0) -> 0 | C17: =IFERROR(COUNTIF(INDIRECT("'"&$A17&"'!$S$22:$S$150"),"Aprovada"),0) -> 0 | D17: =IFERROR(COUNTIF(INDIRECT("'"&$A17&"'!$S$22:$S$150"),"Entregue"),0) -> 0 | E17: =IFERROR(COUNTIF(INDIRECT("'"&$A17&"'!$S$22:$S$150"),"Pendente"),0) -> 0 | F17: =IFERROR(COUNTIF(INDIRECT("'"&$A17&"'!$S$22:$S$150"),"Atrasada"),0) -> 0 | G17: =IFERROR(COUNTIF(INDIRECT("'"&$A17&"'!$S$22:$S$150"),"Reprovada"),0) -> 0 | H17: =IF($B17=0,0,$C17/$B17) -> 0 | I17: =IF($B17=0,"",REPT("█",ROUND($H17*15,0))&REPT("░",15-ROUND($H17*15,0))) | J17: =IF($B17=0,"—",IF($C17=$B17,"Concluído",IF($F17>0,"Com atrasos","Em andamento"))) -> — | L17: =EDATE(DATE(2026,7,1),9) -> 46478
A18: =CHOOSE(MONTH($L18),"JAN","FEV","MAR","ABR","MAI","JUN","JUL","AGO","SET","OUT","NOV","DEZ")&" "&YEAR($L18) -> MAI 2027 | B18: =IFERROR(COUNTIF(INDIRECT("'"&$A18&"'!$S$22:$S$150"),"Aprovada"),0)+IFERROR(COUNTIF(INDIRECT("'"&$A18&"'!$S$22:$S$150"),"Entregue"),0)+IFERROR(COUNTIF(INDIRECT("'"&$A18&"'!$S$22:$S$150"),"Pendente"),0)+IFERROR(COUNTIF(INDIRECT("'"&$A18&"'!$S$22:$S$150"),"Atrasada"),0)+IFERROR(COUNTIF(INDIRECT("'"&$A18&"'!$S$22:$S$150"),"Reprovada"),0) -> 0 | C18: =IFERROR(COUNTIF(INDIRECT("'"&$A18&"'!$S$22:$S$150"),"Aprovada"),0) -> 0 | D18: =IFERROR(COUNTIF(INDIRECT("'"&$A18&"'!$S$22:$S$150"),"Entregue"),0) -> 0 | E18: =IFERROR(COUNTIF(INDIRECT("'"&$A18&"'!$S$22:$S$150"),"Pendente"),0) -> 0 | F18: =IFERROR(COUNTIF(INDIRECT("'"&$A18&"'!$S$22:$S$150"),"Atrasada"),0) -> 0 | G18: =IFERROR(COUNTIF(INDIRECT("'"&$A18&"'!$S$22:$S$150"),"Reprovada"),0) -> 0 | H18: =IF($B18=0,0,$C18/$B18) -> 0 | I18: =IF($B18=0,"",REPT("█",ROUND($H18*15,0))&REPT("░",15-ROUND($H18*15,0))) | J18: =IF($B18=0,"—",IF($C18=$B18,"Concluído",IF($F18>0,"Com atrasos","Em andamento"))) -> — | L18: =EDATE(DATE(2026,7,1),10) -> 46508
A19: =CHOOSE(MONTH($L19),"JAN","FEV","MAR","ABR","MAI","JUN","JUL","AGO","SET","OUT","NOV","DEZ")&" "&YEAR($L19) -> JUN 2027 | B19: =IFERROR(COUNTIF(INDIRECT("'"&$A19&"'!$S$22:$S$150"),"Aprovada"),0)+IFERROR(COUNTIF(INDIRECT("'"&$A19&"'!$S$22:$S$150"),"Entregue"),0)+IFERROR(COUNTIF(INDIRECT("'"&$A19&"'!$S$22:$S$150"),"Pendente"),0)+IFERROR(COUNTIF(INDIRECT("'"&$A19&"'!$S$22:$S$150"),"Atrasada"),0)+IFERROR(COUNTIF(INDIRECT("'"&$A19&"'!$S$22:$S$150"),"Reprovada"),0) -> 0 | C19: =IFERROR(COUNTIF(INDIRECT("'"&$A19&"'!$S$22:$S$150"),"Aprovada"),0) -> 0 | D19: =IFERROR(COUNTIF(INDIRECT("'"&$A19&"'!$S$22:$S$150"),"Entregue"),0) -> 0 | E19: =IFERROR(COUNTIF(INDIRECT("'"&$A19&"'!$S$22:$S$150"),"Pendente"),0) -> 0 | F19: =IFERROR(COUNTIF(INDIRECT("'"&$A19&"'!$S$22:$S$150"),"Atrasada"),0) -> 0 | G19: =IFERROR(COUNTIF(INDIRECT("'"&$A19&"'!$S$22:$S$150"),"Reprovada"),0) -> 0 | H19: =IF($B19=0,0,$C19/$B19) -> 0 | I19: =IF($B19=0,"",REPT("█",ROUND($H19*15,0))&REPT("░",15-ROUND($H19*15,0))) | J19: =IF($B19=0,"—",IF($C19=$B19,"Concluído",IF($F19>0,"Com atrasos","Em andamento"))) -> — | L19: =EDATE(DATE(2026,7,1),11) -> 46539
A20: =CHOOSE(MONTH($L20),"JAN","FEV","MAR","ABR","MAI","JUN","JUL","AGO","SET","OUT","NOV","DEZ")&" "&YEAR($L20) -> JUL 2027 | B20: =IFERROR(COUNTIF(INDIRECT("'"&$A20&"'!$S$22:$S$150"),"Aprovada"),0)+IFERROR(COUNTIF(INDIRECT("'"&$A20&"'!$S$22:$S$150"),"Entregue"),0)+IFERROR(COUNTIF(INDIRECT("'"&$A20&"'!$S$22:$S$150"),"Pendente"),0)+IFERROR(COUNTIF(INDIRECT("'"&$A20&"'!$S$22:$S$150"),"Atrasada"),0)+IFERROR(COUNTIF(INDIRECT("'"&$A20&"'!$S$22:$S$150"),"Reprovada"),0) -> 0 | C20: =IFERROR(COUNTIF(INDIRECT("'"&$A20&"'!$S$22:$S$150"),"Aprovada"),0) -> 0 | D20: =IFERROR(COUNTIF(INDIRECT("'"&$A20&"'!$S$22:$S$150"),"Entregue"),0) -> 0 | E20: =IFERROR(COUNTIF(INDIRECT("'"&$A20&"'!$S$22:$S$150"),"Pendente"),0) -> 0 | F20: =IFERROR(COUNTIF(INDIRECT("'"&$A20&"'!$S$22:$S$150"),"Atrasada"),0) -> 0 | G20: =IFERROR(COUNTIF(INDIRECT("'"&$A20&"'!$S$22:$S$150"),"Reprovada"),0) -> 0 | H20: =IF($B20=0,0,$C20/$B20) -> 0 | I20: =IF($B20=0,"",REPT("█",ROUND($H20*15,0))&REPT("░",15-ROUND($H20*15,0))) | J20: =IF($B20=0,"—",IF($C20=$B20,"Concluído",IF($F20>0,"Com atrasos","Em andamento"))) -> — | L20: =EDATE(DATE(2026,7,1),12) -> 46569
A21: =CHOOSE(MONTH($L21),"JAN","FEV","MAR","ABR","MAI","JUN","JUL","AGO","SET","OUT","NOV","DEZ")&" "&YEAR($L21) -> AGO 2027 | B21: =IFERROR(COUNTIF(INDIRECT("'"&$A21&"'!$S$22:$S$150"),"Aprovada"),0)+IFERROR(COUNTIF(INDIRECT("'"&$A21&"'!$S$22:$S$150"),"Entregue"),0)+IFERROR(COUNTIF(INDIRECT("'"&$A21&"'!$S$22:$S$150"),"Pendente"),0)+IFERROR(COUNTIF(INDIRECT("'"&$A21&"'!$S$22:$S$150"),"Atrasada"),0)+IFERROR(COUNTIF(INDIRECT("'"&$A21&"'!$S$22:$S$150"),"Reprovada"),0) -> 0 | C21: =IFERROR(COUNTIF(INDIRECT("'"&$A21&"'!$S$22:$S$150"),"Aprovada"),0) -> 0 | D21: =IFERROR(COUNTIF(INDIRECT("'"&$A21&"'!$S$22:$S$150"),"Entregue"),0) -> 0 | E21: =IFERROR(COUNTIF(INDIRECT("'"&$A21&"'!$S$22:$S$150"),"Pendente"),0) -> 0 | F21: =IFERROR(COUNTIF(INDIRECT("'"&$A21&"'!$S$22:$S$150"),"Atrasada"),0) -> 0 | G21: =IFERROR(COUNTIF(INDIRECT("'"&$A21&"'!$S$22:$S$150"),"Reprovada"),0) -> 0 | H21: =IF($B21=0,0,$C21/$B21) -> 0 | I21: =IF($B21=0,"",REPT("█",ROUND($H21*15,0))&REPT("░",15-ROUND($H21*15,0))) | J21: =IF($B21=0,"—",IF($C21=$B21,"Concluído",IF($F21>0,"Com atrasos","Em andamento"))) -> — | L21: =EDATE(DATE(2026,7,1),13) -> 46600
A22: =CHOOSE(MONTH($L22),"JAN","FEV","MAR","ABR","MAI","JUN","JUL","AGO","SET","OUT","NOV","DEZ")&" "&YEAR($L22) -> SET 2027 | B22: =IFERROR(COUNTIF(INDIRECT("'"&$A22&"'!$S$22:$S$150"),"Aprovada"),0)+IFERROR(COUNTIF(INDIRECT("'"&$A22&"'!$S$22:$S$150"),"Entregue"),0)+IFERROR(COUNTIF(INDIRECT("'"&$A22&"'!$S$22:$S$150"),"Pendente"),0)+IFERROR(COUNTIF(INDIRECT("'"&$A22&"'!$S$22:$S$150"),"Atrasada"),0)+IFERROR(COUNTIF(INDIRECT("'"&$A22&"'!$S$22:$S$150"),"Reprovada"),0) -> 0 | C22: =IFERROR(COUNTIF(INDIRECT("'"&$A22&"'!$S$22:$S$150"),"Aprovada"),0) -> 0 | D22: =IFERROR(COUNTIF(INDIRECT("'"&$A22&"'!$S$22:$S$150"),"Entregue"),0) -> 0 | E22: =IFERROR(COUNTIF(INDIRECT("'"&$A22&"'!$S$22:$S$150"),"Pendente"),0) -> 0 | F22: =IFERROR(COUNTIF(INDIRECT("'"&$A22&"'!$S$22:$S$150"),"Atrasada"),0) -> 0 | G22: =IFERROR(COUNTIF(INDIRECT("'"&$A22&"'!$S$22:$S$150"),"Reprovada"),0) -> 0 | H22: =IF($B22=0,0,$C22/$B22) -> 0 | I22: =IF($B22=0,"",REPT("█",ROUND($H22*15,0))&REPT("░",15-ROUND($H22*15,0))) | J22: =IF($B22=0,"—",IF($C22=$B22,"Concluído",IF($F22>0,"Com atrasos","Em andamento"))) -> — | L22: =EDATE(DATE(2026,7,1),14) -> 46631
A23: =CHOOSE(MONTH($L23),"JAN","FEV","MAR","ABR","MAI","JUN","JUL","AGO","SET","OUT","NOV","DEZ")&" "&YEAR($L23) -> OUT 2027 | B23: =IFERROR(COUNTIF(INDIRECT("'"&$A23&"'!$S$22:$S$150"),"Aprovada"),0)+IFERROR(COUNTIF(INDIRECT("'"&$A23&"'!$S$22:$S$150"),"Entregue"),0)+IFERROR(COUNTIF(INDIRECT("'"&$A23&"'!$S$22:$S$150"),"Pendente"),0)+IFERROR(COUNTIF(INDIRECT("'"&$A23&"'!$S$22:$S$150"),"Atrasada"),0)+IFERROR(COUNTIF(INDIRECT("'"&$A23&"'!$S$22:$S$150"),"Reprovada"),0) -> 0 | C23: =IFERROR(COUNTIF(INDIRECT("'"&$A23&"'!$S$22:$S$150"),"Aprovada"),0) -> 0 | D23: =IFERROR(COUNTIF(INDIRECT("'"&$A23&"'!$S$22:$S$150"),"Entregue"),0) -> 0 | E23: =IFERROR(COUNTIF(INDIRECT("'"&$A23&"'!$S$22:$S$150"),"Pendente"),0) -> 0 | F23: =IFERROR(COUNTIF(INDIRECT("'"&$A23&"'!$S$22:$S$150"),"Atrasada"),0) -> 0 | G23: =IFERROR(COUNTIF(INDIRECT("'"&$A23&"'!$S$22:$S$150"),"Reprovada"),0) -> 0 | H23: =IF($B23=0,0,$C23/$B23) -> 0 | I23: =IF($B23=0,"",REPT("█",ROUND($H23*15,0))&REPT("░",15-ROUND($H23*15,0))) | J23: =IF($B23=0,"—",IF($C23=$B23,"Concluído",IF($F23>0,"Com atrasos","Em andamento"))) -> — | L23: =EDATE(DATE(2026,7,1),15) -> 46661
A24: =CHOOSE(MONTH($L24),"JAN","FEV","MAR","ABR","MAI","JUN","JUL","AGO","SET","OUT","NOV","DEZ")&" "&YEAR($L24) -> NOV 2027 | B24: =IFERROR(COUNTIF(INDIRECT("'"&$A24&"'!$S$22:$S$150"),"Aprovada"),0)+IFERROR(COUNTIF(INDIRECT("'"&$A24&"'!$S$22:$S$150"),"Entregue"),0)+IFERROR(COUNTIF(INDIRECT("'"&$A24&"'!$S$22:$S$150"),"Pendente"),0)+IFERROR(COUNTIF(INDIRECT("'"&$A24&"'!$S$22:$S$150"),"Atrasada"),0)+IFERROR(COUNTIF(INDIRECT("'"&$A24&"'!$S$22:$S$150"),"Reprovada"),0) -> 0 | C24: =IFERROR(COUNTIF(INDIRECT("'"&$A24&"'!$S$22:$S$150"),"Aprovada"),0) -> 0 | D24: =IFERROR(COUNTIF(INDIRECT("'"&$A24&"'!$S$22:$S$150"),"Entregue"),0) -> 0 | E24: =IFERROR(COUNTIF(INDIRECT("'"&$A24&"'!$S$22:$S$150"),"Pendente"),0) -> 0 | F24: =IFERROR(COUNTIF(INDIRECT("'"&$A24&"'!$S$22:$S$150"),"Atrasada"),0) -> 0 | G24: =IFERROR(COUNTIF(INDIRECT("'"&$A24&"'!$S$22:$S$150"),"Reprovada"),0) -> 0 | H24: =IF($B24=0,0,$C24/$B24) -> 0 | I24: =IF($B24=0,"",REPT("█",ROUND($H24*15,0))&REPT("░",15-ROUND($H24*15,0))) | J24: =IF($B24=0,"—",IF($C24=$B24,"Concluído",IF($F24>0,"Com atrasos","Em andamento"))) -> — | L24: =EDATE(DATE(2026,7,1),16) -> 46692
A25: =CHOOSE(MONTH($L25),"JAN","FEV","MAR","ABR","MAI","JUN","JUL","AGO","SET","OUT","NOV","DEZ")&" "&YEAR($L25) -> DEZ 2027 | B25: =IFERROR(COUNTIF(INDIRECT("'"&$A25&"'!$S$22:$S$150"),"Aprovada"),0)+IFERROR(COUNTIF(INDIRECT("'"&$A25&"'!$S$22:$S$150"),"Entregue"),0)+IFERROR(COUNTIF(INDIRECT("'"&$A25&"'!$S$22:$S$150"),"Pendente"),0)+IFERROR(COUNTIF(INDIRECT("'"&$A25&"'!$S$22:$S$150"),"Atrasada"),0)+IFERROR(COUNTIF(INDIRECT("'"&$A25&"'!$S$22:$S$150"),"Reprovada"),0) -> 0 | C25: =IFERROR(COUNTIF(INDIRECT("'"&$A25&"'!$S$22:$S$150"),"Aprovada"),0) -> 0 | D25: =IFERROR(COUNTIF(INDIRECT("'"&$A25&"'!$S$22:$S$150"),"Entregue"),0) -> 0 | E25: =IFERROR(COUNTIF(INDIRECT("'"&$A25&"'!$S$22:$S$150"),"Pendente"),0) -> 0 | F25: =IFERROR(COUNTIF(INDIRECT("'"&$A25&"'!$S$22:$S$150"),"Atrasada"),0) -> 0 | G25: =IFERROR(COUNTIF(INDIRECT("'"&$A25&"'!$S$22:$S$150"),"Reprovada"),0) -> 0 | H25: =IF($B25=0,0,$C25/$B25) -> 0 | I25: =IF($B25=0,"",REPT("█",ROUND($H25*15,0))&REPT("░",15-ROUND($H25*15,0))) | J25: =IF($B25=0,"—",IF($C25=$B25,"Concluído",IF($F25>0,"Com atrasos","Em andamento"))) -> — | L25: =EDATE(DATE(2026,7,1),17) -> 46722
A26: TOTAL | B26: =SUM(B8:B25) -> 212 | C26: =SUM(C8:C25) -> 0 | D26: =SUM(D8:D25) -> 0 | E26: =SUM(E8:E25) -> 170 | F26: =SUM(F8:F25) -> 42 | G26: =SUM(G8:G25) -> 0 | H26: =IF($B26=0,0,$C26/$B26) -> 0 | I26: =REPT("█",ROUND($H26*15,0))&REPT("░",15-ROUND($H26*15,0)) -> ░░░░░░░░░░░░░░░
A28: DESEMPENHO ACUMULADO POR TURNO
A29: TURNO | B29: TOTAL | C29: APROV. | D29: ATRAS. | E29: % APROV. | F29: PROGRESSO
A30: A | B30: =$C30+$D30+$M30+$N30+$O30 -> 60 | C30: =IFERROR(COUNTIFS(INDIRECT("'"&$A$8&"'!$G$22:$G$150"),$A30,INDIRECT("'"&$A$8&"'!$S$22:$S$150"),"Aprovada"),0)+IFERROR(COUNTIFS(INDIRECT("'"&$A$9&"'!$G$22:$G$150"),$A30,INDIRECT("'"&$A$9&"'!$S$22:$S$150"),"Aprovada"),0)+IFERROR(COUNTIFS(INDIRECT("'"&$A$10&"'!$G$22:$G$150"),$A30,INDIRECT("'"&$A$10&"'!$S$22:$S$150"),"Aprovada"),0)+IFERROR(COUNTIFS(INDIRECT("'"&$A$11&"'!$G$22:$G$150"),$A30,INDIRECT("'"&$A$11&"'!$S$22:$S$150"),"Aprovada"),0)+IFERROR(COUNTIFS(INDIRECT("'"&$A$12&"'!$G$22:$G$150"),$A30,INDIRECT("'"&$A$12&"'!$S$22:$S$150"),"Aprovada"),0)+IFERROR(COUNTIFS(INDIRECT("'"&$A$13&"'!$G$22:$G$150"),$A30,INDIRECT("'"&$A$13&"'!$S$22:$S$150"),"Aprovada"),0)+IFERROR(COUNTIFS(INDIRECT("'"&$A$14&"'!$G$22:$G$150"),$A30,INDIRECT("'"&$A$14&"'!$S$22:$S$150"),"Aprovada"),0)+IFERROR(COUNTIFS(INDIRECT("'"&$A$15&"'!$G$22:$G$150"),$A30,INDIRECT("'"&$A$15&"'!$S$22:$S$150"),"Aprovada"),0)+IFERROR(COUNTIFS(INDIRECT("'"&$A$16&"'!$G$22:$G$150"),$A30,INDIRECT("'"&$A$16&"'!$S$22:$S$150"),"Aprovada"),0)+IFERROR(COUNTIFS(INDIRECT("'"&$A$17&"'!$G$22:$G$150"),$A30,INDIRECT("'"&$A$17&"'!$S$22:$S$150"),"Aprovada"),0)+IFERROR(COUNTIFS(INDIRECT("'"&$A$18&"'!$G$22:$G$150"),$A30,INDIRECT("'"&$A$18&"'!$S$22:$S$150"),"Aprovada"),0)+IFERROR(COUNTIFS(INDIRECT("'"&$A$19&"'!$G$22:$G$150"),$A30,INDIRECT("'"&$A$19&"'!$S$22:$S$150"),"Aprovada"),0)+IFERROR(COUNTIFS(INDIRECT("'"&$A$20&"'!$G$22:$G$150"),$A30,INDIRECT("'"&$A$20&"'!$S$22:$S$150"),"Aprovada"),0)+IFERROR(COUNTIFS(INDIRECT("'"&$A$21&"'!$G$22:$G$150"),$A30,INDIRECT("'"&$A$21&"'!$S$22:$S$150"),"Aprovada"),0)+IFERROR(COUNTIFS(INDIRECT("'"&$A$22&"'!$G$22:$G$150"),$A30,INDIRECT("'"&$A$22&"'!$S$22:$S$150"),"Aprovada"),0)+IFERROR(COUNTIFS(INDIRECT("'"&$A$23&"'!$G$22:$G$150"),$A30,INDIRECT("'"&$A$23&"'!$S$22:$S$150"),"Aprovada"),0)+IFERROR(COUNTIFS(INDIRECT("'"&$A$24&"'!$G$22:$G$150"),$A30,INDIRECT("'"&$A$24&"'!$S$22:$S$150"),"Aprovada"),0)+IFERROR(COUNTIFS(INDIRECT("'"&$A$25&"'!$G$22:$G$150"),$A30,INDIRECT("'"&$A$25&"'!$S$22:$S$150"),"Aprovada"),0) -> 0 | D30: =IFERROR(COUNTIFS(INDIRECT("'"&$A$8&"'!$G$22:$G$150"),$A30,INDIRECT("'"&$A$8&"'!$S$22:$S$150"),"Atrasada"),0)+IFERROR(COUNTIFS(INDIRECT("'"&$A$9&"'!$G$22:$G$150"),$A30,INDIRECT("'"&$A$9&"'!$S$22:$S$150"),"Atrasada"),0)+IFERROR(COUNTIFS(INDIRECT("'"&$A$10&"'!$G$22:$G$150"),$A30,INDIRECT("'"&$A$10&"'!$S$22:$S$150"),"Atrasada"),0)+IFERROR(COUNTIFS(INDIRECT("'"&$A$11&"'!$G$22:$G$150"),$A30,INDIRECT("'"&$A$11&"'!$S$22:$S$150"),"Atrasada"),0)+IFERROR(COUNTIFS(INDIRECT("'"&$A$12&"'!$G$22:$G$150"),$A30,INDIRECT("'"&$A$12&"'!$S$22:$S$150"),"Atrasada"),0)+IFERROR(COUNTIFS(INDIRECT("'"&$A$13&"'!$G$22:$G$150"),$A30,INDIRECT("'"&$A$13&"'!$S$22:$S$150"),"Atrasada"),0)+IFERROR(COUNTIFS(INDIRECT("'"&$A$14&"'!$G$22:$G$150"),$A30,INDIRECT("'"&$A$14&"'!$S$22:$S$150"),"Atrasada"),0)+IFERROR(COUNTIFS(INDIRECT("'"&$A$15&"'!$G$22:$G$150"),$A30,INDIRECT("'"&$A$15&"'!$S$22:$S$150"),"Atrasada"),0)+IFERROR(COUNTIFS(INDIRECT("'"&$A$16&"'!$G$22:$G$150"),$A30,INDIRECT("'"&$A$16&"'!$S$22:$S$150"),"Atrasada"),0)+IFERROR(COUNTIFS(INDIRECT("'"&$A$17&"'!$G$22:$G$150"),$A30,INDIRECT("'"&$A$17&"'!$S$22:$S$150"),"Atrasada"),0)+IFERROR(COUNTIFS(INDIRECT("'"&$A$18&"'!$G$22:$G$150"),$A30,INDIRECT("'"&$A$18&"'!$S$22:$S$150"),"Atrasada"),0)+IFERROR(COUNTIFS(INDIRECT("'"&$A$19&"'!$G$22:$G$150"),$A30,INDIRECT("'"&$A$19&"'!$S$22:$S$150"),"Atrasada"),0)+IFERROR(COUNTIFS(INDIRECT("'"&$A$20&"'!$G$22:$G$150"),$A30,INDIRECT("'"&$A$20&"'!$S$22:$S$150"),"Atrasada"),0)+IFERROR(COUNTIFS(INDIRECT("'"&$A$21&"'!$G$22:$G$150"),$A30,INDIRECT("'"&$A$21&"'!$S$22:$S$150"),"Atrasada"),0)+IFERROR(COUNTIFS(INDIRECT("'"&$A$22&"'!$G$22:$G$150"),$A30,INDIRECT("'"&$A$22&"'!$S$22:$S$150"),"Atrasada"),0)+IFERROR(COUNTIFS(INDIRECT("'"&$A$23&"'!$G$22:$G$150"),$A30,INDIRECT("'"&$A$23&"'!$S$22:$S$150"),"Atrasada"),0)+IFERROR(COUNTIFS(INDIRECT("'"&$A$24&"'!$G$22:$G$150"),$A30,INDIRECT("'"&$A$24&"'!$S$22:$S$150"),"Atrasada"),0)+IFERROR(COUNTIFS(INDIRECT("'"&$A$25&"'!$G$22:$G$150"),$A30,INDIRECT("'"&$A$25&"'!$S$22:$S$150"),"Atrasada"),0) -> 12 | E30: =IF($B30=0,0,$C30/$B30) -> 0 | F30: =REPT("█",ROUND($E30*15,0))&REPT("░",15-ROUND($E30*15,0)) -> ░░░░░░░░░░░░░░░ | M30: =IFERROR(COUNTIFS(INDIRECT("'"&$A$8&"'!$G$22:$G$150"),$A30,INDIRECT("'"&$A$8&"'!$S$22:$S$150"),"Entregue"),0)+IFERROR(COUNTIFS(INDIRECT("'"&$A$9&"'!$G$22:$G$150"),$A30,INDIRECT("'"&$A$9&"'!$S$22:$S$150"),"Entregue"),0)+IFERROR(COUNTIFS(INDIRECT("'"&$A$10&"'!$G$22:$G$150"),$A30,INDIRECT("'"&$A$10&"'!$S$22:$S$150"),"Entregue"),0)+IFERROR(COUNTIFS(INDIRECT("'"&$A$11&"'!$G$22:$G$150"),$A30,INDIRECT("'"&$A$11&"'!$S$22:$S$150"),"Entregue"),0)+IFERROR(COUNTIFS(INDIRECT("'"&$A$12&"'!$G$22:$G$150"),$A30,INDIRECT("'"&$A$12&"'!$S$22:$S$150"),"Entregue"),0)+IFERROR(COUNTIFS(INDIRECT("'"&$A$13&"'!$G$22:$G$150"),$A30,INDIRECT("'"&$A$13&"'!$S$22:$S$150"),"Entregue"),0)+IFERROR(COUNTIFS(INDIRECT("'"&$A$14&"'!$G$22:$G$150"),$A30,INDIRECT("'"&$A$14&"'!$S$22:$S$150"),"Entregue"),0)+IFERROR(COUNTIFS(INDIRECT("'"&$A$15&"'!$G$22:$G$150"),$A30,INDIRECT("'"&$A$15&"'!$S$22:$S$150"),"Entregue"),0)+IFERROR(COUNTIFS(INDIRECT("'"&$A$16&"'!$G$22:$G$150"),$A30,INDIRECT("'"&$A$16&"'!$S$22:$S$150"),"Entregue"),0)+IFERROR(COUNTIFS(INDIRECT("'"&$A$17&"'!$G$22:$G$150"),$A30,INDIRECT("'"&$A$17&"'!$S$22:$S$150"),"Entregue"),0)+IFERROR(COUNTIFS(INDIRECT("'"&$A$18&"'!$G$22:$G$150"),$A30,INDIRECT("'"&$A$18&"'!$S$22:$S$150"),"Entregue"),0)+IFERROR(COUNTIFS(INDIRECT("'"&$A$19&"'!$G$22:$G$150"),$A30,INDIRECT("'"&$A$19&"'!$S$22:$S$150"),"Entregue"),0)+IFERROR(COUNTIFS(INDIRECT("'"&$A$20&"'!$G$22:$G$150"),$A30,INDIRECT("'"&$A$20&"'!$S$22:$S$150"),"Entregue"),0)+IFERROR(COUNTIFS(INDIRECT("'"&$A$21&"'!$G$22:$G$150"),$A30,INDIRECT("'"&$A$21&"'!$S$22:$S$150"),"Entregue"),0)+IFERROR(COUNTIFS(INDIRECT("'"&$A$22&"'!$G$22:$G$150"),$A30,INDIRECT("'"&$A$22&"'!$S$22:$S$150"),"Entregue"),0)+IFERROR(COUNTIFS(INDIRECT("'"&$A$23&"'!$G$22:$G$150"),$A30,INDIRECT("'"&$A$23&"'!$S$22:$S$150"),"Entregue"),0)+IFERROR(COUNTIFS(INDIRECT("'"&$A$24&"'!$G$22:$G$150"),$A30,INDIRECT("'"&$A$24&"'!$S$22:$S$150"),"Entregue"),0)+IFERROR(COUNTIFS(INDIRECT("'"&$A$25&"'!$G$22:$G$150"),$A30,INDIRECT("'"&$A$25&"'!$S$22:$S$150"),"Entregue"),0) -> 0 | N30: =IFERROR(COUNTIFS(INDIRECT("'"&$A$8&"'!$G$22:$G$150"),$A30,INDIRECT("'"&$A$8&"'!$S$22:$S$150"),"Pendente"),0)+IFERROR(COUNTIFS(INDIRECT("'"&$A$9&"'!$G$22:$G$150"),$A30,INDIRECT("'"&$A$9&"'!$S$22:$S$150"),"Pendente"),0)+IFERROR(COUNTIFS(INDIRECT("'"&$A$10&"'!$G$22:$G$150"),$A30,INDIRECT("'"&$A$10&"'!$S$22:$S$150"),"Pendente"),0)+IFERROR(COUNTIFS(INDIRECT("'"&$A$11&"'!$G$22:$G$150"),$A30,INDIRECT("'"&$A$11&"'!$S$22:$S$150"),"Pendente"),0)+IFERROR(COUNTIFS(INDIRECT("'"&$A$12&"'!$G$22:$G$150"),$A30,INDIRECT("'"&$A$12&"'!$S$22:$S$150"),"Pendente"),0)+IFERROR(COUNTIFS(INDIRECT("'"&$A$13&"'!$G$22:$G$150"),$A30,INDIRECT("'"&$A$13&"'!$S$22:$S$150"),"Pendente"),0)+IFERROR(COUNTIFS(INDIRECT("'"&$A$14&"'!$G$22:$G$150"),$A30,INDIRECT("'"&$A$14&"'!$S$22:$S$150"),"Pendente"),0)+IFERROR(COUNTIFS(INDIRECT("'"&$A$15&"'!$G$22:$G$150"),$A30,INDIRECT("'"&$A$15&"'!$S$22:$S$150"),"Pendente"),0)+IFERROR(COUNTIFS(INDIRECT("'"&$A$16&"'!$G$22:$G$150"),$A30,INDIRECT("'"&$A$16&"'!$S$22:$S$150"),"Pendente"),0)+IFERROR(COUNTIFS(INDIRECT("'"&$A$17&"'!$G$22:$G$150"),$A30,INDIRECT("'"&$A$17&"'!$S$22:$S$150"),"Pendente"),0)+IFERROR(COUNTIFS(INDIRECT("'"&$A$18&"'!$G$22:$G$150"),$A30,INDIRECT("'"&$A$18&"'!$S$22:$S$150"),"Pendente"),0)+IFERROR(COUNTIFS(INDIRECT("'"&$A$19&"'!$G$22:$G$150"),$A30,INDIRECT("'"&$A$19&"'!$S$22:$S$150"),"Pendente"),0)+IFERROR(COUNTIFS(INDIRECT("'"&$A$20&"'!$G$22:$G$150"),$A30,INDIRECT("'"&$A$20&"'!$S$22:$S$150"),"Pendente"),0)+IFERROR(COUNTIFS(INDIRECT("'"&$A$21&"'!$G$22:$G$150"),$A30,INDIRECT("'"&$A$21&"'!$S$22:$S$150"),"Pendente"),0)+IFERROR(COUNTIFS(INDIRECT("'"&$A$22&"'!$G$22:$G$150"),$A30,INDIRECT("'"&$A$22&"'!$S$22:$S$150"),"Pendente"),0)+IFERROR(COUNTIFS(INDIRECT("'"&$A$23&"'!$G$22:$G$150"),$A30,INDIRECT("'"&$A$23&"'!$S$22:$S$150"),"Pendente"),0)+IFERROR(COUNTIFS(INDIRECT("'"&$A$24&"'!$G$22:$G$150"),$A30,INDIRECT("'"&$A$24&"'!$S$22:$S$150"),"Pendente"),0)+IFERROR(COUNTIFS(INDIRECT("'"&$A$25&"'!$G$22:$G$150"),$A30,INDIRECT("'"&$A$25&"'!$S$22:$S$150"),"Pendente"),0) -> 48 | O30: =IFERROR(COUNTIFS(INDIRECT("'"&$A$8&"'!$G$22:$G$150"),$A30,INDIRECT("'"&$A$8&"'!$S$22:$S$150"),"Reprovada"),0)+IFERROR(COUNTIFS(INDIRECT("'"&$A$9&"'!$G$22:$G$150"),$A30,INDIRECT("'"&$A$9&"'!$S$22:$S$150"),"Reprovada"),0)+IFERROR(COUNTIFS(INDIRECT("'"&$A$10&"'!$G$22:$G$150"),$A30,INDIRECT("'"&$A$10&"'!$S$22:$S$150"),"Reprovada"),0)+IFERROR(COUNTIFS(INDIRECT("'"&$A$11&"'!$G$22:$G$150"),$A30,INDIRECT("'"&$A$11&"'!$S$22:$S$150"),"Reprovada"),0)+IFERROR(COUNTIFS(INDIRECT("'"&$A$12&"'!$G$22:$G$150"),$A30,INDIRECT("'"&$A$12&"'!$S$22:$S$150"),"Reprovada"),0)+IFERROR(COUNTIFS(INDIRECT("'"&$A$13&"'!$G$22:$G$150"),$A30,INDIRECT("'"&$A$13&"'!$S$22:$S$150"),"Reprovada"),0)+IFERROR(COUNTIFS(INDIRECT("'"&$A$14&"'!$G$22:$G$150"),$A30,INDIRECT("'"&$A$14&"'!$S$22:$S$150"),"Reprovada"),0)+IFERROR(COUNTIFS(INDIRECT("'"&$A$15&"'!$G$22:$G$150"),$A30,INDIRECT("'"&$A$15&"'!$S$22:$S$150"),"Reprovada"),0)+IFERROR(COUNTIFS(INDIRECT("'"&$A$16&"'!$G$22:$G$150"),$A30,INDIRECT("'"&$A$16&"'!$S$22:$S$150"),"Reprovada"),0)+IFERROR(COUNTIFS(INDIRECT("'"&$A$17&"'!$G$22:$G$150"),$A30,INDIRECT("'"&$A$17&"'!$S$22:$S$150"),"Reprovada"),0)+IFERROR(COUNTIFS(INDIRECT("'"&$A$18&"'!$G$22:$G$150"),$A30,INDIRECT("'"&$A$18&"'!$S$22:$S$150"),"Reprovada"),0)+IFERROR(COUNTIFS(INDIRECT("'"&$A$19&"'!$G$22:$G$150"),$A30,INDIRECT("'"&$A$19&"'!$S$22:$S$150"),"Reprovada"),0)+IFERROR(COUNTIFS(INDIRECT("'"&$A$20&"'!$G$22:$G$150"),$A30,INDIRECT("'"&$A$20&"'!$S$22:$S$150"),"Reprovada"),0)+IFERROR(COUNTIFS(INDIRECT("'"&$A$21&"'!$G$22:$G$150"),$A30,INDIRECT("'"&$A$21&"'!$S$22:$S$150"),"Reprovada"),0)+IFERROR(COUNTIFS(INDIRECT("'"&$A$22&"'!$G$22:$G$150"),$A30,INDIRECT("'"&$A$22&"'!$S$22:$S$150"),"Reprovada"),0)+IFERROR(COUNTIFS(INDIRECT("'"&$A$23&"'!$G$22:$G$150"),$A30,INDIRECT("'"&$A$23&"'!$S$22:$S$150"),"Reprovada"),0)+IFERROR(COUNTIFS(INDIRECT("'"&$A$24&"'!$G$22:$G$150"),$A30,INDIRECT("'"&$A$24&"'!$S$22:$S$150"),"Reprovada"),0)+IFERROR(COUNTIFS(INDIRECT("'"&$A$25&"'!$G$22:$G$150"),$A30,INDIRECT("'"&$A$25&"'!$S$22:$S$150"),"Reprovada"),0) -> 0
A31: B | B31: =$C31+$D31+$M31+$N31+$O31 -> 60 | C31: =IFERROR(COUNTIFS(INDIRECT("'"&$A$8&"'!$G$22:$G$150"),$A31,INDIRECT("'"&$A$8&"'!$S$22:$S$150"),"Aprovada"),0)+IFERROR(COUNTIFS(INDIRECT("'"&$A$9&"'!$G$22:$G$150"),$A31,INDIRECT("'"&$A$9&"'!$S$22:$S$150"),"Aprovada"),0)+IFERROR(COUNTIFS(INDIRECT("'"&$A$10&"'!$G$22:$G$150"),$A31,INDIRECT("'"&$A$10&"'!$S$22:$S$150"),"Aprovada"),0)+IFERROR(COUNTIFS(INDIRECT("'"&$A$11&"'!$G$22:$G$150"),$A31,INDIRECT("'"&$A$11&"'!$S$22:$S$150"),"Aprovada"),0)+IFERROR(COUNTIFS(INDIRECT("'"&$A$12&"'!$G$22:$G$150"),$A31,INDIRECT("'"&$A$12&"'!$S$22:$S$150"),"Aprovada"),0)+IFERROR(COUNTIFS(INDIRECT("'"&$A$13&"'!$G$22:$G$150"),$A31,INDIRECT("'"&$A$13&"'!$S$22:$S$150"),"Aprovada"),0)+IFERROR(COUNTIFS(INDIRECT("'"&$A$14&"'!$G$22:$G$150"),$A31,INDIRECT("'"&$A$14&"'!$S$22:$S$150"),"Aprovada"),0)+IFERROR(COUNTIFS(INDIRECT("'"&$A$15&"'!$G$22:$G$150"),$A31,INDIRECT("'"&$A$15&"'!$S$22:$S$150"),"Aprovada"),0)+IFERROR(COUNTIFS(INDIRECT("'"&$A$16&"'!$G$22:$G$150"),$A31,INDIRECT("'"&$A$16&"'!$S$22:$S$150"),"Aprovada"),0)+IFERROR(COUNTIFS(INDIRECT("'"&$A$17&"'!$G$22:$G$150"),$A31,INDIRECT("'"&$A$17&"'!$S$22:$S$150"),"Aprovada"),0)+IFERROR(COUNTIFS(INDIRECT("'"&$A$18&"'!$G$22:$G$150"),$A31,INDIRECT("'"&$A$18&"'!$S$22:$S$150"),"Aprovada"),0)+IFERROR(COUNTIFS(INDIRECT("'"&$A$19&"'!$G$22:$G$150"),$A31,INDIRECT("'"&$A$19&"'!$S$22:$S$150"),"Aprovada"),0)+IFERROR(COUNTIFS(INDIRECT("'"&$A$20&"'!$G$22:$G$150"),$A31,INDIRECT("'"&$A$20&"'!$S$22:$S$150"),"Aprovada"),0)+IFERROR(COUNTIFS(INDIRECT("'"&$A$21&"'!$G$22:$G$150"),$A31,INDIRECT("'"&$A$21&"'!$S$22:$S$150"),"Aprovada"),0)+IFERROR(COUNTIFS(INDIRECT("'"&$A$22&"'!$G$22:$G$150"),$A31,INDIRECT("'"&$A$22&"'!$S$22:$S$150"),"Aprovada"),0)+IFERROR(COUNTIFS(INDIRECT("'"&$A$23&"'!$G$22:$G$150"),$A31,INDIRECT("'"&$A$23&"'!$S$22:$S$150"),"Aprovada"),0)+IFERROR(COUNTIFS(INDIRECT("'"&$A$24&"'!$G$22:$G$150"),$A31,INDIRECT("'"&$A$24&"'!$S$22:$S$150"),"Aprovada"),0)+IFERROR(COUNTIFS(INDIRECT("'"&$A$25&"'!$G$22:$G$150"),$A31,INDIRECT("'"&$A$25&"'!$S$22:$S$150"),"Aprovada"),0) -> 0 | D31: =IFERROR(COUNTIFS(INDIRECT("'"&$A$8&"'!$G$22:$G$150"),$A31,INDIRECT("'"&$A$8&"'!$S$22:$S$150"),"Atrasada"),0)+IFERROR(COUNTIFS(INDIRECT("'"&$A$9&"'!$G$22:$G$150"),$A31,INDIRECT("'"&$A$9&"'!$S$22:$S$150"),"Atrasada"),0)+IFERROR(COUNTIFS(INDIRECT("'"&$A$10&"'!$G$22:$G$150"),$A31,INDIRECT("'"&$A$10&"'!$S$22:$S$150"),"Atrasada"),0)+IFERROR(COUNTIFS(INDIRECT("'"&$A$11&"'!$G$22:$G$150"),$A31,INDIRECT("'"&$A$11&"'!$S$22:$S$150"),"Atrasada"),0)+IFERROR(COUNTIFS(INDIRECT("'"&$A$12&"'!$G$22:$G$150"),$A31,INDIRECT("'"&$A$12&"'!$S$22:$S$150"),"Atrasada"),0)+IFERROR(COUNTIFS(INDIRECT("'"&$A$13&"'!$G$22:$G$150"),$A31,INDIRECT("'"&$A$13&"'!$S$22:$S$150"),"Atrasada"),0)+IFERROR(COUNTIFS(INDIRECT("'"&$A$14&"'!$G$22:$G$150"),$A31,INDIRECT("'"&$A$14&"'!$S$22:$S$150"),"Atrasada"),0)+IFERROR(COUNTIFS(INDIRECT("'"&$A$15&"'!$G$22:$G$150"),$A31,INDIRECT("'"&$A$15&"'!$S$22:$S$150"),"Atrasada"),0)+IFERROR(COUNTIFS(INDIRECT("'"&$A$16&"'!$G$22:$G$150"),$A31,INDIRECT("'"&$A$16&"'!$S$22:$S$150"),"Atrasada"),0)+IFERROR(COUNTIFS(INDIRECT("'"&$A$17&"'!$G$22:$G$150"),$A31,INDIRECT("'"&$A$17&"'!$S$22:$S$150"),"Atrasada"),0)+IFERROR(COUNTIFS(INDIRECT("'"&$A$18&"'!$G$22:$G$150"),$A31,INDIRECT("'"&$A$18&"'!$S$22:$S$150"),"Atrasada"),0)+IFERROR(COUNTIFS(INDIRECT("'"&$A$19&"'!$G$22:$G$150"),$A31,INDIRECT("'"&$A$19&"'!$S$22:$S$150"),"Atrasada"),0)+IFERROR(COUNTIFS(INDIRECT("'"&$A$20&"'!$G$22:$G$150"),$A31,INDIRECT("'"&$A$20&"'!$S$22:$S$150"),"Atrasada"),0)+IFERROR(COUNTIFS(INDIRECT("'"&$A$21&"'!$G$22:$G$150"),$A31,INDIRECT("'"&$A$21&"'!$S$22:$S$150"),"Atrasada"),0)+IFERROR(COUNTIFS(INDIRECT("'"&$A$22&"'!$G$22:$G$150"),$A31,INDIRECT("'"&$A$22&"'!$S$22:$S$150"),"Atrasada"),0)+IFERROR(COUNTIFS(INDIRECT("'"&$A$23&"'!$G$22:$G$150"),$A31,INDIRECT("'"&$A$23&"'!$S$22:$S$150"),"Atrasada"),0)+IFERROR(COUNTIFS(INDIRECT("'"&$A$24&"'!$G$22:$G$150"),$A31,INDIRECT("'"&$A$24&"'!$S$22:$S$150"),"Atrasada"),0)+IFERROR(COUNTIFS(INDIRECT("'"&$A$25&"'!$G$22:$G$150"),$A31,INDIRECT("'"&$A$25&"'!$S$22:$S$150"),"Atrasada"),0) -> 12 | E31: =IF($B31=0,0,$C31/$B31) -> 0 | F31: =REPT("█",ROUND($E31*15,0))&REPT("░",15-ROUND($E31*15,0)) -> ░░░░░░░░░░░░░░░ | M31: =IFERROR(COUNTIFS(INDIRECT("'"&$A$8&"'!$G$22:$G$150"),$A31,INDIRECT("'"&$A$8&"'!$S$22:$S$150"),"Entregue"),0)+IFERROR(COUNTIFS(INDIRECT("'"&$A$9&"'!$G$22:$G$150"),$A31,INDIRECT("'"&$A$9&"'!$S$22:$S$150"),"Entregue"),0)+IFERROR(COUNTIFS(INDIRECT("'"&$A$10&"'!$G$22:$G$150"),$A31,INDIRECT("'"&$A$10&"'!$S$22:$S$150"),"Entregue"),0)+IFERROR(COUNTIFS(INDIRECT("'"&$A$11&"'!$G$22:$G$150"),$A31,INDIRECT("'"&$A$11&"'!$S$22:$S$150"),"Entregue"),0)+IFERROR(COUNTIFS(INDIRECT("'"&$A$12&"'!$G$22:$G$150"),$A31,INDIRECT("'"&$A$12&"'!$S$22:$S$150"),"Entregue"),0)+IFERROR(COUNTIFS(INDIRECT("'"&$A$13&"'!$G$22:$G$150"),$A31,INDIRECT("'"&$A$13&"'!$S$22:$S$150"),"Entregue"),0)+IFERROR(COUNTIFS(INDIRECT("'"&$A$14&"'!$G$22:$G$150"),$A31,INDIRECT("'"&$A$14&"'!$S$22:$S$150"),"Entregue"),0)+IFERROR(COUNTIFS(INDIRECT("'"&$A$15&"'!$G$22:$G$150"),$A31,INDIRECT("'"&$A$15&"'!$S$22:$S$150"),"Entregue"),0)+IFERROR(COUNTIFS(INDIRECT("'"&$A$16&"'!$G$22:$G$150"),$A31,INDIRECT("'"&$A$16&"'!$S$22:$S$150"),"Entregue"),0)+IFERROR(COUNTIFS(INDIRECT("'"&$A$17&"'!$G$22:$G$150"),$A31,INDIRECT("'"&$A$17&"'!$S$22:$S$150"),"Entregue"),0)+IFERROR(COUNTIFS(INDIRECT("'"&$A$18&"'!$G$22:$G$150"),$A31,INDIRECT("'"&$A$18&"'!$S$22:$S$150"),"Entregue"),0)+IFERROR(COUNTIFS(INDIRECT("'"&$A$19&"'!$G$22:$G$150"),$A31,INDIRECT("'"&$A$19&"'!$S$22:$S$150"),"Entregue"),0)+IFERROR(COUNTIFS(INDIRECT("'"&$A$20&"'!$G$22:$G$150"),$A31,INDIRECT("'"&$A$20&"'!$S$22:$S$150"),"Entregue"),0)+IFERROR(COUNTIFS(INDIRECT("'"&$A$21&"'!$G$22:$G$150"),$A31,INDIRECT("'"&$A$21&"'!$S$22:$S$150"),"Entregue"),0)+IFERROR(COUNTIFS(INDIRECT("'"&$A$22&"'!$G$22:$G$150"),$A31,INDIRECT("'"&$A$22&"'!$S$22:$S$150"),"Entregue"),0)+IFERROR(COUNTIFS(INDIRECT("'"&$A$23&"'!$G$22:$G$150"),$A31,INDIRECT("'"&$A$23&"'!$S$22:$S$150"),"Entregue"),0)+IFERROR(COUNTIFS(INDIRECT("'"&$A$24&"'!$G$22:$G$150"),$A31,INDIRECT("'"&$A$24&"'!$S$22:$S$150"),"Entregue"),0)+IFERROR(COUNTIFS(INDIRECT("'"&$A$25&"'!$G$22:$G$150"),$A31,INDIRECT("'"&$A$25&"'!$S$22:$S$150"),"Entregue"),0) -> 0 | N31: =IFERROR(COUNTIFS(INDIRECT("'"&$A$8&"'!$G$22:$G$150"),$A31,INDIRECT("'"&$A$8&"'!$S$22:$S$150"),"Pendente"),0)+IFERROR(COUNTIFS(INDIRECT("'"&$A$9&"'!$G$22:$G$150"),$A31,INDIRECT("'"&$A$9&"'!$S$22:$S$150"),"Pendente"),0)+IFERROR(COUNTIFS(INDIRECT("'"&$A$10&"'!$G$22:$G$150"),$A31,INDIRECT("'"&$A$10&"'!$S$22:$S$150"),"Pendente"),0)+IFERROR(COUNTIFS(INDIRECT("'"&$A$11&"'!$G$22:$G$150"),$A31,INDIRECT("'"&$A$11&"'!$S$22:$S$150"),"Pendente"),0)+IFERROR(COUNTIFS(INDIRECT("'"&$A$12&"'!$G$22:$G$150"),$A31,INDIRECT("'"&$A$12&"'!$S$22:$S$150"),"Pendente"),0)+IFERROR(COUNTIFS(INDIRECT("'"&$A$13&"'!$G$22:$G$150"),$A31,INDIRECT("'"&$A$13&"'!$S$22:$S$150"),"Pendente"),0)+IFERROR(COUNTIFS(INDIRECT("'"&$A$14&"'!$G$22:$G$150"),$A31,INDIRECT("'"&$A$14&"'!$S$22:$S$150"),"Pendente"),0)+IFERROR(COUNTIFS(INDIRECT("'"&$A$15&"'!$G$22:$G$150"),$A31,INDIRECT("'"&$A$15&"'!$S$22:$S$150"),"Pendente"),0)+IFERROR(COUNTIFS(INDIRECT("'"&$A$16&"'!$G$22:$G$150"),$A31,INDIRECT("'"&$A$16&"'!$S$22:$S$150"),"Pendente"),0)+IFERROR(COUNTIFS(INDIRECT("'"&$A$17&"'!$G$22:$G$150"),$A31,INDIRECT("'"&$A$17&"'!$S$22:$S$150"),"Pendente"),0)+IFERROR(COUNTIFS(INDIRECT("'"&$A$18&"'!$G$22:$G$150"),$A31,INDIRECT("'"&$A$18&"'!$S$22:$S$150"),"Pendente"),0)+IFERROR(COUNTIFS(INDIRECT("'"&$A$19&"'!$G$22:$G$150"),$A31,INDIRECT("'"&$A$19&"'!$S$22:$S$150"),"Pendente"),0)+IFERROR(COUNTIFS(INDIRECT("'"&$A$20&"'!$G$22:$G$150"),$A31,INDIRECT("'"&$A$20&"'!$S$22:$S$150"),"Pendente"),0)+IFERROR(COUNTIFS(INDIRECT("'"&$A$21&"'!$G$22:$G$150"),$A31,INDIRECT("'"&$A$21&"'!$S$22:$S$150"),"Pendente"),0)+IFERROR(COUNTIFS(INDIRECT("'"&$A$22&"'!$G$22:$G$150"),$A31,INDIRECT("'"&$A$22&"'!$S$22:$S$150"),"Pendente"),0)+IFERROR(COUNTIFS(INDIRECT("'"&$A$23&"'!$G$22:$G$150"),$A31,INDIRECT("'"&$A$23&"'!$S$22:$S$150"),"Pendente"),0)+IFERROR(COUNTIFS(INDIRECT("'"&$A$24&"'!$G$22:$G$150"),$A31,INDIRECT("'"&$A$24&"'!$S$22:$S$150"),"Pendente"),0)+IFERROR(COUNTIFS(INDIRECT("'"&$A$25&"'!$G$22:$G$150"),$A31,INDIRECT("'"&$A$25&"'!$S$22:$S$150"),"Pendente"),0) -> 48 | O31: =IFERROR(COUNTIFS(INDIRECT("'"&$A$8&"'!$G$22:$G$150"),$A31,INDIRECT("'"&$A$8&"'!$S$22:$S$150"),"Reprovada"),0)+IFERROR(COUNTIFS(INDIRECT("'"&$A$9&"'!$G$22:$G$150"),$A31,INDIRECT("'"&$A$9&"'!$S$22:$S$150"),"Reprovada"),0)+IFERROR(COUNTIFS(INDIRECT("'"&$A$10&"'!$G$22:$G$150"),$A31,INDIRECT("'"&$A$10&"'!$S$22:$S$150"),"Reprovada"),0)+IFERROR(COUNTIFS(INDIRECT("'"&$A$11&"'!$G$22:$G$150"),$A31,INDIRECT("'"&$A$11&"'!$S$22:$S$150"),"Reprovada"),0)+IFERROR(COUNTIFS(INDIRECT("'"&$A$12&"'!$G$22:$G$150"),$A31,INDIRECT("'"&$A$12&"'!$S$22:$S$150"),"Reprovada"),0)+IFERROR(COUNTIFS(INDIRECT("'"&$A$13&"'!$G$22:$G$150"),$A31,INDIRECT("'"&$A$13&"'!$S$22:$S$150"),"Reprovada"),0)+IFERROR(COUNTIFS(INDIRECT("'"&$A$14&"'!$G$22:$G$150"),$A31,INDIRECT("'"&$A$14&"'!$S$22:$S$150"),"Reprovada"),0)+IFERROR(COUNTIFS(INDIRECT("'"&$A$15&"'!$G$22:$G$150"),$A31,INDIRECT("'"&$A$15&"'!$S$22:$S$150"),"Reprovada"),0)+IFERROR(COUNTIFS(INDIRECT("'"&$A$16&"'!$G$22:$G$150"),$A31,INDIRECT("'"&$A$16&"'!$S$22:$S$150"),"Reprovada"),0)+IFERROR(COUNTIFS(INDIRECT("'"&$A$17&"'!$G$22:$G$150"),$A31,INDIRECT("'"&$A$17&"'!$S$22:$S$150"),"Reprovada"),0)+IFERROR(COUNTIFS(INDIRECT("'"&$A$18&"'!$G$22:$G$150"),$A31,INDIRECT("'"&$A$18&"'!$S$22:$S$150"),"Reprovada"),0)+IFERROR(COUNTIFS(INDIRECT("'"&$A$19&"'!$G$22:$G$150"),$A31,INDIRECT("'"&$A$19&"'!$S$22:$S$150"),"Reprovada"),0)+IFERROR(COUNTIFS(INDIRECT("'"&$A$20&"'!$G$22:$G$150"),$A31,INDIRECT("'"&$A$20&"'!$S$22:$S$150"),"Reprovada"),0)+IFERROR(COUNTIFS(INDIRECT("'"&$A$21&"'!$G$22:$G$150"),$A31,INDIRECT("'"&$A$21&"'!$S$22:$S$150"),"Reprovada"),0)+IFERROR(COUNTIFS(INDIRECT("'"&$A$22&"'!$G$22:$G$150"),$A31,INDIRECT("'"&$A$22&"'!$S$22:$S$150"),"Reprovada"),0)+IFERROR(COUNTIFS(INDIRECT("'"&$A$23&"'!$G$22:$G$150"),$A31,INDIRECT("'"&$A$23&"'!$S$22:$S$150"),"Reprovada"),0)+IFERROR(COUNTIFS(INDIRECT("'"&$A$24&"'!$G$22:$G$150"),$A31,INDIRECT("'"&$A$24&"'!$S$22:$S$150"),"Reprovada"),0)+IFERROR(COUNTIFS(INDIRECT("'"&$A$25&"'!$G$22:$G$150"),$A31,INDIRECT("'"&$A$25&"'!$S$22:$S$150"),"Reprovada"),0) -> 0
A32: C | B32: =$C32+$D32+$M32+$N32+$O32 -> 60 | C32: =IFERROR(COUNTIFS(INDIRECT("'"&$A$8&"'!$G$22:$G$150"),$A32,INDIRECT("'"&$A$8&"'!$S$22:$S$150"),"Aprovada"),0)+IFERROR(COUNTIFS(INDIRECT("'"&$A$9&"'!$G$22:$G$150"),$A32,INDIRECT("'"&$A$9&"'!$S$22:$S$150"),"Aprovada"),0)+IFERROR(COUNTIFS(INDIRECT("'"&$A$10&"'!$G$22:$G$150"),$A32,INDIRECT("'"&$A$10&"'!$S$22:$S$150"),"Aprovada"),0)+IFERROR(COUNTIFS(INDIRECT("'"&$A$11&"'!$G$22:$G$150"),$A32,INDIRECT("'"&$A$11&"'!$S$22:$S$150"),"Aprovada"),0)+IFERROR(COUNTIFS(INDIRECT("'"&$A$12&"'!$G$22:$G$150"),$A32,INDIRECT("'"&$A$12&"'!$S$22:$S$150"),"Aprovada"),0)+IFERROR(COUNTIFS(INDIRECT("'"&$A$13&"'!$G$22:$G$150"),$A32,INDIRECT("'"&$A$13&"'!$S$22:$S$150"),"Aprovada"),0)+IFERROR(COUNTIFS(INDIRECT("'"&$A$14&"'!$G$22:$G$150"),$A32,INDIRECT("'"&$A$14&"'!$S$22:$S$150"),"Aprovada"),0)+IFERROR(COUNTIFS(INDIRECT("'"&$A$15&"'!$G$22:$G$150"),$A32,INDIRECT("'"&$A$15&"'!$S$22:$S$150"),"Aprovada"),0)+IFERROR(COUNTIFS(INDIRECT("'"&$A$16&"'!$G$22:$G$150"),$A32,INDIRECT("'"&$A$16&"'!$S$22:$S$150"),"Aprovada"),0)+IFERROR(COUNTIFS(INDIRECT("'"&$A$17&"'!$G$22:$G$150"),$A32,INDIRECT("'"&$A$17&"'!$S$22:$S$150"),"Aprovada"),0)+IFERROR(COUNTIFS(INDIRECT("'"&$A$18&"'!$G$22:$G$150"),$A32,INDIRECT("'"&$A$18&"'!$S$22:$S$150"),"Aprovada"),0)+IFERROR(COUNTIFS(INDIRECT("'"&$A$19&"'!$G$22:$G$150"),$A32,INDIRECT("'"&$A$19&"'!$S$22:$S$150"),"Aprovada"),0)+IFERROR(COUNTIFS(INDIRECT("'"&$A$20&"'!$G$22:$G$150"),$A32,INDIRECT("'"&$A$20&"'!$S$22:$S$150"),"Aprovada"),0)+IFERROR(COUNTIFS(INDIRECT("'"&$A$21&"'!$G$22:$G$150"),$A32,INDIRECT("'"&$A$21&"'!$S$22:$S$150"),"Aprovada"),0)+IFERROR(COUNTIFS(INDIRECT("'"&$A$22&"'!$G$22:$G$150"),$A32,INDIRECT("'"&$A$22&"'!$S$22:$S$150"),"Aprovada"),0)+IFERROR(COUNTIFS(INDIRECT("'"&$A$23&"'!$G$22:$G$150"),$A32,INDIRECT("'"&$A$23&"'!$S$22:$S$150"),"Aprovada"),0)+IFERROR(COUNTIFS(INDIRECT("'"&$A$24&"'!$G$22:$G$150"),$A32,INDIRECT("'"&$A$24&"'!$S$22:$S$150"),"Aprovada"),0)+IFERROR(COUNTIFS(INDIRECT("'"&$A$25&"'!$G$22:$G$150"),$A32,INDIRECT("'"&$A$25&"'!$S$22:$S$150"),"Aprovada"),0) -> 0 | D32: =IFERROR(COUNTIFS(INDIRECT("'"&$A$8&"'!$G$22:$G$150"),$A32,INDIRECT("'"&$A$8&"'!$S$22:$S$150"),"Atrasada"),0)+IFERROR(COUNTIFS(INDIRECT("'"&$A$9&"'!$G$22:$G$150"),$A32,INDIRECT("'"&$A$9&"'!$S$22:$S$150"),"Atrasada"),0)+IFERROR(COUNTIFS(INDIRECT("'"&$A$10&"'!$G$22:$G$150"),$A32,INDIRECT("'"&$A$10&"'!$S$22:$S$150"),"Atrasada"),0)+IFERROR(COUNTIFS(INDIRECT("'"&$A$11&"'!$G$22:$G$150"),$A32,INDIRECT("'"&$A$11&"'!$S$22:$S$150"),"Atrasada"),0)+IFERROR(COUNTIFS(INDIRECT("'"&$A$12&"'!$G$22:$G$150"),$A32,INDIRECT("'"&$A$12&"'!$S$22:$S$150"),"Atrasada"),0)+IFERROR(COUNTIFS(INDIRECT("'"&$A$13&"'!$G$22:$G$150"),$A32,INDIRECT("'"&$A$13&"'!$S$22:$S$150"),"Atrasada"),0)+IFERROR(COUNTIFS(INDIRECT("'"&$A$14&"'!$G$22:$G$150"),$A32,INDIRECT("'"&$A$14&"'!$S$22:$S$150"),"Atrasada"),0)+IFERROR(COUNTIFS(INDIRECT("'"&$A$15&"'!$G$22:$G$150"),$A32,INDIRECT("'"&$A$15&"'!$S$22:$S$150"),"Atrasada"),0)+IFERROR(COUNTIFS(INDIRECT("'"&$A$16&"'!$G$22:$G$150"),$A32,INDIRECT("'"&$A$16&"'!$S$22:$S$150"),"Atrasada"),0)+IFERROR(COUNTIFS(INDIRECT("'"&$A$17&"'!$G$22:$G$150"),$A32,INDIRECT("'"&$A$17&"'!$S$22:$S$150"),"Atrasada"),0)+IFERROR(COUNTIFS(INDIRECT("'"&$A$18&"'!$G$22:$G$150"),$A32,INDIRECT("'"&$A$18&"'!$S$22:$S$150"),"Atrasada"),0)+IFERROR(COUNTIFS(INDIRECT("'"&$A$19&"'!$G$22:$G$150"),$A32,INDIRECT("'"&$A$19&"'!$S$22:$S$150"),"Atrasada"),0)+IFERROR(COUNTIFS(INDIRECT("'"&$A$20&"'!$G$22:$G$150"),$A32,INDIRECT("'"&$A$20&"'!$S$22:$S$150"),"Atrasada"),0)+IFERROR(COUNTIFS(INDIRECT("'"&$A$21&"'!$G$22:$G$150"),$A32,INDIRECT("'"&$A$21&"'!$S$22:$S$150"),"Atrasada"),0)+IFERROR(COUNTIFS(INDIRECT("'"&$A$22&"'!$G$22:$G$150"),$A32,INDIRECT("'"&$A$22&"'!$S$22:$S$150"),"Atrasada"),0)+IFERROR(COUNTIFS(INDIRECT("'"&$A$23&"'!$G$22:$G$150"),$A32,INDIRECT("'"&$A$23&"'!$S$22:$S$150"),"Atrasada"),0)+IFERROR(COUNTIFS(INDIRECT("'"&$A$24&"'!$G$22:$G$150"),$A32,INDIRECT("'"&$A$24&"'!$S$22:$S$150"),"Atrasada"),0)+IFERROR(COUNTIFS(INDIRECT("'"&$A$25&"'!$G$22:$G$150"),$A32,INDIRECT("'"&$A$25&"'!$S$22:$S$150"),"Atrasada"),0) -> 12 | E32: =IF($B32=0,0,$C32/$B32) -> 0 | F32: =REPT("█",ROUND($E32*15,0))&REPT("░",15-ROUND($E32*15,0)) -> ░░░░░░░░░░░░░░░ | M32: =IFERROR(COUNTIFS(INDIRECT("'"&$A$8&"'!$G$22:$G$150"),$A32,INDIRECT("'"&$A$8&"'!$S$22:$S$150"),"Entregue"),0)+IFERROR(COUNTIFS(INDIRECT("'"&$A$9&"'!$G$22:$G$150"),$A32,INDIRECT("'"&$A$9&"'!$S$22:$S$150"),"Entregue"),0)+IFERROR(COUNTIFS(INDIRECT("'"&$A$10&"'!$G$22:$G$150"),$A32,INDIRECT("'"&$A$10&"'!$S$22:$S$150"),"Entregue"),0)+IFERROR(COUNTIFS(INDIRECT("'"&$A$11&"'!$G$22:$G$150"),$A32,INDIRECT("'"&$A$11&"'!$S$22:$S$150"),"Entregue"),0)+IFERROR(COUNTIFS(INDIRECT("'"&$A$12&"'!$G$22:$G$150"),$A32,INDIRECT("'"&$A$12&"'!$S$22:$S$150"),"Entregue"),0)+IFERROR(COUNTIFS(INDIRECT("'"&$A$13&"'!$G$22:$G$150"),$A32,INDIRECT("'"&$A$13&"'!$S$22:$S$150"),"Entregue"),0)+IFERROR(COUNTIFS(INDIRECT("'"&$A$14&"'!$G$22:$G$150"),$A32,INDIRECT("'"&$A$14&"'!$S$22:$S$150"),"Entregue"),0)+IFERROR(COUNTIFS(INDIRECT("'"&$A$15&"'!$G$22:$G$150"),$A32,INDIRECT("'"&$A$15&"'!$S$22:$S$150"),"Entregue"),0)+IFERROR(COUNTIFS(INDIRECT("'"&$A$16&"'!$G$22:$G$150"),$A32,INDIRECT("'"&$A$16&"'!$S$22:$S$150"),"Entregue"),0)+IFERROR(COUNTIFS(INDIRECT("'"&$A$17&"'!$G$22:$G$150"),$A32,INDIRECT("'"&$A$17&"'!$S$22:$S$150"),"Entregue"),0)+IFERROR(COUNTIFS(INDIRECT("'"&$A$18&"'!$G$22:$G$150"),$A32,INDIRECT("'"&$A$18&"'!$S$22:$S$150"),"Entregue"),0)+IFERROR(COUNTIFS(INDIRECT("'"&$A$19&"'!$G$22:$G$150"),$A32,INDIRECT("'"&$A$19&"'!$S$22:$S$150"),"Entregue"),0)+IFERROR(COUNTIFS(INDIRECT("'"&$A$20&"'!$G$22:$G$150"),$A32,INDIRECT("'"&$A$20&"'!$S$22:$S$150"),"Entregue"),0)+IFERROR(COUNTIFS(INDIRECT("'"&$A$21&"'!$G$22:$G$150"),$A32,INDIRECT("'"&$A$21&"'!$S$22:$S$150"),"Entregue"),0)+IFERROR(COUNTIFS(INDIRECT("'"&$A$22&"'!$G$22:$G$150"),$A32,INDIRECT("'"&$A$22&"'!$S$22:$S$150"),"Entregue"),0)+IFERROR(COUNTIFS(INDIRECT("'"&$A$23&"'!$G$22:$G$150"),$A32,INDIRECT("'"&$A$23&"'!$S$22:$S$150"),"Entregue"),0)+IFERROR(COUNTIFS(INDIRECT("'"&$A$24&"'!$G$22:$G$150"),$A32,INDIRECT("'"&$A$24&"'!$S$22:$S$150"),"Entregue"),0)+IFERROR(COUNTIFS(INDIRECT("'"&$A$25&"'!$G$22:$G$150"),$A32,INDIRECT("'"&$A$25&"'!$S$22:$S$150"),"Entregue"),0) -> 0 | N32: =IFERROR(COUNTIFS(INDIRECT("'"&$A$8&"'!$G$22:$G$150"),$A32,INDIRECT("'"&$A$8&"'!$S$22:$S$150"),"Pendente"),0)+IFERROR(COUNTIFS(INDIRECT("'"&$A$9&"'!$G$22:$G$150"),$A32,INDIRECT("'"&$A$9&"'!$S$22:$S$150"),"Pendente"),0)+IFERROR(COUNTIFS(INDIRECT("'"&$A$10&"'!$G$22:$G$150"),$A32,INDIRECT("'"&$A$10&"'!$S$22:$S$150"),"Pendente"),0)+IFERROR(COUNTIFS(INDIRECT("'"&$A$11&"'!$G$22:$G$150"),$A32,INDIRECT("'"&$A$11&"'!$S$22:$S$150"),"Pendente"),0)+IFERROR(COUNTIFS(INDIRECT("'"&$A$12&"'!$G$22:$G$150"),$A32,INDIRECT("'"&$A$12&"'!$S$22:$S$150"),"Pendente"),0)+IFERROR(COUNTIFS(INDIRECT("'"&$A$13&"'!$G$22:$G$150"),$A32,INDIRECT("'"&$A$13&"'!$S$22:$S$150"),"Pendente"),0)+IFERROR(COUNTIFS(INDIRECT("'"&$A$14&"'!$G$22:$G$150"),$A32,INDIRECT("'"&$A$14&"'!$S$22:$S$150"),"Pendente"),0)+IFERROR(COUNTIFS(INDIRECT("'"&$A$15&"'!$G$22:$G$150"),$A32,INDIRECT("'"&$A$15&"'!$S$22:$S$150"),"Pendente"),0)+IFERROR(COUNTIFS(INDIRECT("'"&$A$16&"'!$G$22:$G$150"),$A32,INDIRECT("'"&$A$16&"'!$S$22:$S$150"),"Pendente"),0)+IFERROR(COUNTIFS(INDIRECT("'"&$A$17&"'!$G$22:$G$150"),$A32,INDIRECT("'"&$A$17&"'!$S$22:$S$150"),"Pendente"),0)+IFERROR(COUNTIFS(INDIRECT("'"&$A$18&"'!$G$22:$G$150"),$A32,INDIRECT("'"&$A$18&"'!$S$22:$S$150"),"Pendente"),0)+IFERROR(COUNTIFS(INDIRECT("'"&$A$19&"'!$G$22:$G$150"),$A32,INDIRECT("'"&$A$19&"'!$S$22:$S$150"),"Pendente"),0)+IFERROR(COUNTIFS(INDIRECT("'"&$A$20&"'!$G$22:$G$150"),$A32,INDIRECT("'"&$A$20&"'!$S$22:$S$150"),"Pendente"),0)+IFERROR(COUNTIFS(INDIRECT("'"&$A$21&"'!$G$22:$G$150"),$A32,INDIRECT("'"&$A$21&"'!$S$22:$S$150"),"Pendente"),0)+IFERROR(COUNTIFS(INDIRECT("'"&$A$22&"'!$G$22:$G$150"),$A32,INDIRECT("'"&$A$22&"'!$S$22:$S$150"),"Pendente"),0)+IFERROR(COUNTIFS(INDIRECT("'"&$A$23&"'!$G$22:$G$150"),$A32,INDIRECT("'"&$A$23&"'!$S$22:$S$150"),"Pendente"),0)+IFERROR(COUNTIFS(INDIRECT("'"&$A$24&"'!$G$22:$G$150"),$A32,INDIRECT("'"&$A$24&"'!$S$22:$S$150"),"Pendente"),0)+IFERROR(COUNTIFS(INDIRECT("'"&$A$25&"'!$G$22:$G$150"),$A32,INDIRECT("'"&$A$25&"'!$S$22:$S$150"),"Pendente"),0) -> 48 | O32: =IFERROR(COUNTIFS(INDIRECT("'"&$A$8&"'!$G$22:$G$150"),$A32,INDIRECT("'"&$A$8&"'!$S$22:$S$150"),"Reprovada"),0)+IFERROR(COUNTIFS(INDIRECT("'"&$A$9&"'!$G$22:$G$150"),$A32,INDIRECT("'"&$A$9&"'!$S$22:$S$150"),"Reprovada"),0)+IFERROR(COUNTIFS(INDIRECT("'"&$A$10&"'!$G$22:$G$150"),$A32,INDIRECT("'"&$A$10&"'!$S$22:$S$150"),"Reprovada"),0)+IFERROR(COUNTIFS(INDIRECT("'"&$A$11&"'!$G$22:$G$150"),$A32,INDIRECT("'"&$A$11&"'!$S$22:$S$150"),"Reprovada"),0)+IFERROR(COUNTIFS(INDIRECT("'"&$A$12&"'!$G$22:$G$150"),$A32,INDIRECT("'"&$A$12&"'!$S$22:$S$150"),"Reprovada"),0)+IFERROR(COUNTIFS(INDIRECT("'"&$A$13&"'!$G$22:$G$150"),$A32,INDIRECT("'"&$A$13&"'!$S$22:$S$150"),"Reprovada"),0)+IFERROR(COUNTIFS(INDIRECT("'"&$A$14&"'!$G$22:$G$150"),$A32,INDIRECT("'"&$A$14&"'!$S$22:$S$150"),"Reprovada"),0)+IFERROR(COUNTIFS(INDIRECT("'"&$A$15&"'!$G$22:$G$150"),$A32,INDIRECT("'"&$A$15&"'!$S$22:$S$150"),"Reprovada"),0)+IFERROR(COUNTIFS(INDIRECT("'"&$A$16&"'!$G$22:$G$150"),$A32,INDIRECT("'"&$A$16&"'!$S$22:$S$150"),"Reprovada"),0)+IFERROR(COUNTIFS(INDIRECT("'"&$A$17&"'!$G$22:$G$150"),$A32,INDIRECT("'"&$A$17&"'!$S$22:$S$150"),"Reprovada"),0)+IFERROR(COUNTIFS(INDIRECT("'"&$A$18&"'!$G$22:$G$150"),$A32,INDIRECT("'"&$A$18&"'!$S$22:$S$150"),"Reprovada"),0)+IFERROR(COUNTIFS(INDIRECT("'"&$A$19&"'!$G$22:$G$150"),$A32,INDIRECT("'"&$A$19&"'!$S$22:$S$150"),"Reprovada"),0)+IFERROR(COUNTIFS(INDIRECT("'"&$A$20&"'!$G$22:$G$150"),$A32,INDIRECT("'"&$A$20&"'!$S$22:$S$150"),"Reprovada"),0)+IFERROR(COUNTIFS(INDIRECT("'"&$A$21&"'!$G$22:$G$150"),$A32,INDIRECT("'"&$A$21&"'!$S$22:$S$150"),"Reprovada"),0)+IFERROR(COUNTIFS(INDIRECT("'"&$A$22&"'!$G$22:$G$150"),$A32,INDIRECT("'"&$A$22&"'!$S$22:$S$150"),"Reprovada"),0)+IFERROR(COUNTIFS(INDIRECT("'"&$A$23&"'!$G$22:$G$150"),$A32,INDIRECT("'"&$A$23&"'!$S$22:$S$150"),"Reprovada"),0)+IFERROR(COUNTIFS(INDIRECT("'"&$A$24&"'!$G$22:$G$150"),$A32,INDIRECT("'"&$A$24&"'!$S$22:$S$150"),"Reprovada"),0)+IFERROR(COUNTIFS(INDIRECT("'"&$A$25&"'!$G$22:$G$150"),$A32,INDIRECT("'"&$A$25&"'!$S$22:$S$150"),"Reprovada"),0) -> 0
A34: "Aguard. valid." = entregue e à espera do Aprovado/Reprovado. Análises de erros, absenteísmo e tendências: aba PAINEL.

Sheet CONFIG
A1: CONFIG — EQUIPE, SETORES E PARÂMETROS
A3: 1 · EQUIPE (usada nas fórmulas e nos e-mails do script)
A4: PAPEL | B4: NOME | C4: E-MAIL
A5: Coordenador · Turno A (manhã) | B5: (preencha o nome) | C5: turnoA@bartofil.com.br
A6: Coordenador · Turno B (tarde) | B6: (preencha o nome) | C6: turnoB@bartofil.com.br
A7: Coordenador · Turno C (noite) | B7: (preencha o nome) | C7: turnoC@bartofil.com.br
A8: Gerente de Logística | B8: (preencha o nome) | C8: gerente@bartofil.com.br
A9: Administrador da planilha | B9: Hércules | C9: hercules@bartofil.com.br
A11: 2 · SETORES DO CD (lista do campo 'Setor' e das ocorrências) | C11: 3 · PARÂMETROS DO SCRIPT
A12: Recebimento | C12: Janela de "próximos prazos" no e-mail matinal (dias) | D12: 7
A13: Conferência | C13: Copiar a gestão no digesto após atraso de (dias) | D13: 2
A14: Armazenagem / Porta-paletes | C14: E-mail em cópia (opcional)
A15: Separação (Picking) | C15: Pasta do Drive p/ entregas (o script cria e preenche)
A16: Reposição | C16: E-mail da diretoria p/ relatório mensal (opcional)
A17: Expedição
A18: Carregamento / Docas
A19: Devolução / Avarias
A20: Inventário
A21: Manutenção
A22: Pátio / Área externa
A23: Administrativo do CD
A41: Células em amarelo são editáveis. NÃO mova linhas/colunas desta aba: o script lê B5:C9, D12:D16 e A12:A40 (setores — só nomes de setor nessa faixa).
A42: Para editar setores, SOBRESCREVA ou LIMPE células (Delete). Não exclua linhas — se o menu suspenso quebrar, use GSL Bartofil > Reaplicar lista de setores.

Sheet JUL 2026
A1: 07 · JULHO 2026 — CALENDÁRIO OPERACIONAL | X1: 46204
X2: JUL
A3: =IF((COUNTIF($S$22:$S$143,"Aprovada")+COUNTIF($S$22:$S$143,"Entregue")+COUNTIF($S$22:$S$143,"Pendente")+COUNTIF($S$22:$S$143,"Atrasada")+COUNTIF($S$22:$S$143,"Reprovada"))=0,"",IF(COUNTIF($S$22:$S$143,"Aprovada")=(COUNTIF($S$22:$S$143,"Aprovada")+COUNTIF($S$22:$S$143,"Entregue")+COUNTIF($S$22:$S$143,"Pendente")+COUNTIF($S$22:$S$143,"Atrasada")+COUNTIF($S$22:$S$143,"Reprovada")),"MÊS CONCLUÍDO — todas as atividades aprovadas","EM ANDAMENTO — "&COUNTIF($S$22:$S$143,"Aprovada")&" de "&(COUNTIF($S$22:$S$143,"Aprovada")+COUNTIF($S$22:$S$143,"Entregue")+COUNTIF($S$22:$S$143,"Pendente")+COUNTIF($S$22:$S$143,"Atrasada")+COUNTIF($S$22:$S$143,"Reprovada"))&" atividades aprovadas · "&COUNTIF($S$22:$S$143,"Atrasada")&" em atraso")) -> EM ANDAMENTO — 0 de 39 atividades aprovadas · 39 em atraso
B5: DOM | D5: SEG | F5: TER | H5: QUA | J5: QUI | L5: SEX | N5: SÁB
B6: =IF(MONTH($X$1-WEEKDAY($X$1)+1+0)=MONTH($X$1),$X$1-WEEKDAY($X$1)+1+0,"") | D6: =IF(MONTH($X$1-WEEKDAY($X$1)+1+1)=MONTH($X$1),$X$1-WEEKDAY($X$1)+1+1,"") | F6: =IF(MONTH($X$1-WEEKDAY($X$1)+1+2)=MONTH($X$1),$X$1-WEEKDAY($X$1)+1+2,"") | H6: =IF(MONTH($X$1-WEEKDAY($X$1)+1+3)=MONTH($X$1),$X$1-WEEKDAY($X$1)+1+3,"") -> 46204 | J6: =IF(MONTH($X$1-WEEKDAY($X$1)+1+4)=MONTH($X$1),$X$1-WEEKDAY($X$1)+1+4,"") -> 46205 | L6: =IF(MONTH($X$1-WEEKDAY($X$1)+1+5)=MONTH($X$1),$X$1-WEEKDAY($X$1)+1+5,"") -> 46206 | N6: =IF(MONTH($X$1-WEEKDAY($X$1)+1+6)=MONTH($X$1),$X$1-WEEKDAY($X$1)+1+6,"") -> 46207
